13308-ERROR-unhandled exception in instance <MyHandler(id=1412910986336, addr='127.0.0.1:51098', user='vrv.lfm@Gmail.com')>
Traceback (most recent call last):
  File "C:\Users\devvr\AppData\Local\Programs\Python\Python38\lib\asyncore.py", line 83, in read
    obj.handle_read_event()
  File "C:\Users\devvr\AppData\Local\Programs\Python\Python38\lib\asyncore.py", line 420, in handle_read_event
    self.handle_read()
  File "C:\Users\devvr\AppData\Local\Programs\Python\Python38\lib\site-packages\pyftpdlib\ioloop.py", line 922, in handle_read
    asynchat.async_chat.handle_read(self)
  File "C:\Users\devvr\AppData\Local\Programs\Python\Python38\lib\asynchat.py", line 171, in handle_read
    self.found_terminator()
  File "C:\Users\devvr\AppData\Local\Programs\Python\Python38\lib\site-packages\pyftpdlib\handlers.py", line 1449, in found_terminator
    self.pre_process_command(line, cmd, arg)
  File "C:\Users\devvr\AppData\Local\Programs\Python\Python38\lib\site-packages\pyftpdlib\handlers.py", line 1498, in pre_process_command
    self.process_command(cmd, arg)
  File "C:\Users\devvr\AppData\Local\Programs\Python\Python38\lib\site-packages\pyftpdlib\handlers.py", line 1577, in process_command
    method(*args, **kwargs)
  File "C:\Users\devvr\AppData\Local\Programs\Python\Python38\lib\site-packages\pyftpdlib\handlers.py", line 2595, in ftp_PASS
    self.authorizer.validate_authentication(self.username, line, self)
  File "a:\code\Current\dj\core\ftp\tempCodeRunnerFile.py", line 127, in validate_authentication
    content = json.loads(req.content)
  File "C:\Users\devvr\AppData\Local\Programs\Python\Python38\lib\json\__init__.py", line 357, in loads
    return _default_decoder.decode(s)
  File "C:\Users\devvr\AppData\Local\Programs\Python\Python38\lib\json\decoder.py", line 337, in decode
    obj, end = self.raw_decode(s, idx=_w(s, 0).end())
  File "C:\Users\devvr\AppData\Local\Programs\Python\Python38\lib\json\decoder.py", line 355, in raw_decode
    raise JSONDecodeError("Expecting value", s, err.value) from None
json.decoder.JSONDecodeError: Expecting value: line 2 column 1 (char 1)
13308-ERROR-unhandled exception in instance <MyHandler(id=1412910986336, addr='127.0.0.1:51100', user='vrv.lfm@Gmail.com')>
Traceback (most recent call last):
  File "C:\Users\devvr\AppData\Local\Programs\Python\Python38\lib\asyncore.py", line 83, in read
    obj.handle_read_event()
  File "C:\Users\devvr\AppData\Local\Programs\Python\Python38\lib\asyncore.py", line 420, in handle_read_event
    self.handle_read()
  File "C:\Users\devvr\AppData\Local\Programs\Python\Python38\lib\site-packages\pyftpdlib\ioloop.py", line 922, in handle_read
    asynchat.async_chat.handle_read(self)
  File "C:\Users\devvr\AppData\Local\Programs\Python\Python38\lib\asynchat.py", line 171, in handle_read
    self.found_terminator()
  File "C:\Users\devvr\AppData\Local\Programs\Python\Python38\lib\site-packages\pyftpdlib\handlers.py", line 1449, in found_terminator
    self.pre_process_command(line, cmd, arg)
  File "C:\Users\devvr\AppData\Local\Programs\Python\Python38\lib\site-packages\pyftpdlib\handlers.py", line 1498, in pre_process_command
    self.process_command(cmd, arg)
  File "C:\Users\devvr\AppData\Local\Programs\Python\Python38\lib\site-packages\pyftpdlib\handlers.py", line 1577, in process_command
    method(*args, **kwargs)
  File "C:\Users\devvr\AppData\Local\Programs\Python\Python38\lib\site-packages\pyftpdlib\handlers.py", line 2595, in ftp_PASS
    self.authorizer.validate_authentication(self.username, line, self)
  File "a:\code\Current\dj\core\ftp\tempCodeRunnerFile.py", line 127, in validate_authentication
    content = json.loads(req.content)
  File "C:\Users\devvr\AppData\Local\Programs\Python\Python38\lib\json\__init__.py", line 357, in loads
    return _default_decoder.decode(s)
  File "C:\Users\devvr\AppData\Local\Programs\Python\Python38\lib\json\decoder.py", line 337, in decode
    obj, end = self.raw_decode(s, idx=_w(s, 0).end())
  File "C:\Users\devvr\AppData\Local\Programs\Python\Python38\lib\json\decoder.py", line 355, in raw_decode
    raise JSONDecodeError("Expecting value", s, err.value) from None
json.decoder.JSONDecodeError: Expecting value: line 2 column 1 (char 1)
13308-ERROR-unhandled exception in instance <MyHandler(id=1412910986336, addr='127.0.0.1:51102', user='vrv.lfm@Gmail.com')>
Traceback (most recent call last):
  File "C:\Users\devvr\AppData\Local\Programs\Python\Python38\lib\asyncore.py", line 83, in read
    obj.handle_read_event()
  File "C:\Users\devvr\AppData\Local\Programs\Python\Python38\lib\asyncore.py", line 420, in handle_read_event
    self.handle_read()
  File "C:\Users\devvr\AppData\Local\Programs\Python\Python38\lib\site-packages\pyftpdlib\ioloop.py", line 922, in handle_read
    asynchat.async_chat.handle_read(self)
  File "C:\Users\devvr\AppData\Local\Programs\Python\Python38\lib\asynchat.py", line 171, in handle_read
    self.found_terminator()
  File "C:\Users\devvr\AppData\Local\Programs\Python\Python38\lib\site-packages\pyftpdlib\handlers.py", line 1449, in found_terminator
    self.pre_process_command(line, cmd, arg)
  File "C:\Users\devvr\AppData\Local\Programs\Python\Python38\lib\site-packages\pyftpdlib\handlers.py", line 1498, in pre_process_command
    self.process_command(cmd, arg)
  File "C:\Users\devvr\AppData\Local\Programs\Python\Python38\lib\site-packages\pyftpdlib\handlers.py", line 1577, in process_command
    method(*args, **kwargs)
  File "C:\Users\devvr\AppData\Local\Programs\Python\Python38\lib\site-packages\pyftpdlib\handlers.py", line 2595, in ftp_PASS
    self.authorizer.validate_authentication(self.username, line, self)
  File "a:\code\Current\dj\core\ftp\tempCodeRunnerFile.py", line 127, in validate_authentication
    content = json.loads(req.content)
  File "C:\Users\devvr\AppData\Local\Programs\Python\Python38\lib\json\__init__.py", line 357, in loads
    return _default_decoder.decode(s)
  File "C:\Users\devvr\AppData\Local\Programs\Python\Python38\lib\json\decoder.py", line 337, in decode
    obj, end = self.raw_decode(s, idx=_w(s, 0).end())
  File "C:\Users\devvr\AppData\Local\Programs\Python\Python38\lib\json\decoder.py", line 355, in raw_decode
    raise JSONDecodeError("Expecting value", s, err.value) from None
json.decoder.JSONDecodeError: Expecting value: line 2 column 1 (char 1)
13308-ERROR-unhandled exception in instance <MyHandler(id=1412910986336, addr='127.0.0.1:51105', user='vrv.lfm@Gmail.com')>
Traceback (most recent call last):
  File "C:\Users\devvr\AppData\Local\Programs\Python\Python38\lib\asyncore.py", line 83, in read
    obj.handle_read_event()
  File "C:\Users\devvr\AppData\Local\Programs\Python\Python38\lib\asyncore.py", line 420, in handle_read_event
    self.handle_read()
  File "C:\Users\devvr\AppData\Local\Programs\Python\Python38\lib\site-packages\pyftpdlib\ioloop.py", line 922, in handle_read
    asynchat.async_chat.handle_read(self)
  File "C:\Users\devvr\AppData\Local\Programs\Python\Python38\lib\asynchat.py", line 171, in handle_read
    self.found_terminator()
  File "C:\Users\devvr\AppData\Local\Programs\Python\Python38\lib\site-packages\pyftpdlib\handlers.py", line 1449, in found_terminator
    self.pre_process_command(line, cmd, arg)
  File "C:\Users\devvr\AppData\Local\Programs\Python\Python38\lib\site-packages\pyftpdlib\handlers.py", line 1498, in pre_process_command
    self.process_command(cmd, arg)
  File "C:\Users\devvr\AppData\Local\Programs\Python\Python38\lib\site-packages\pyftpdlib\handlers.py", line 1577, in process_command
    method(*args, **kwargs)
  File "C:\Users\devvr\AppData\Local\Programs\Python\Python38\lib\site-packages\pyftpdlib\handlers.py", line 2595, in ftp_PASS
    self.authorizer.validate_authentication(self.username, line, self)
  File "a:\code\Current\dj\core\ftp\tempCodeRunnerFile.py", line 127, in validate_authentication
    content = json.loads(req.content)
  File "C:\Users\devvr\AppData\Local\Programs\Python\Python38\lib\json\__init__.py", line 357, in loads
    return _default_decoder.decode(s)
  File "C:\Users\devvr\AppData\Local\Programs\Python\Python38\lib\json\decoder.py", line 337, in decode
    obj, end = self.raw_decode(s, idx=_w(s, 0).end())
  File "C:\Users\devvr\AppData\Local\Programs\Python\Python38\lib\json\decoder.py", line 355, in raw_decode
    raise JSONDecodeError("Expecting value", s, err.value) from None
json.decoder.JSONDecodeError: Expecting value: line 2 column 1 (char 1)
12920-ERROR-unhandled exception in instance <MyHandler(id=3168572453984, addr='127.0.0.1:51148', user='vrv.lfm@Gmail.com')>
Traceback (most recent call last):
  File "C:\Users\devvr\AppData\Local\Programs\Python\Python38\lib\asyncore.py", line 83, in read
    obj.handle_read_event()
  File "C:\Users\devvr\AppData\Local\Programs\Python\Python38\lib\asyncore.py", line 420, in handle_read_event
    self.handle_read()
  File "C:\Users\devvr\AppData\Local\Programs\Python\Python38\lib\site-packages\pyftpdlib\ioloop.py", line 922, in handle_read
    asynchat.async_chat.handle_read(self)
  File "C:\Users\devvr\AppData\Local\Programs\Python\Python38\lib\asynchat.py", line 171, in handle_read
    self.found_terminator()
  File "C:\Users\devvr\AppData\Local\Programs\Python\Python38\lib\site-packages\pyftpdlib\handlers.py", line 1449, in found_terminator
    self.pre_process_command(line, cmd, arg)
  File "C:\Users\devvr\AppData\Local\Programs\Python\Python38\lib\site-packages\pyftpdlib\handlers.py", line 1498, in pre_process_command
    self.process_command(cmd, arg)
  File "C:\Users\devvr\AppData\Local\Programs\Python\Python38\lib\site-packages\pyftpdlib\handlers.py", line 1577, in process_command
    method(*args, **kwargs)
  File "C:\Users\devvr\AppData\Local\Programs\Python\Python38\lib\site-packages\pyftpdlib\handlers.py", line 2595, in ftp_PASS
    self.authorizer.validate_authentication(self.username, line, self)
  File "a:\code\Current\dj\core\ftp\tempCodeRunnerFile.py", line 127, in validate_authentication
    content = json.loads(req.content)
  File "C:\Users\devvr\AppData\Local\Programs\Python\Python38\lib\json\__init__.py", line 357, in loads
    return _default_decoder.decode(s)
  File "C:\Users\devvr\AppData\Local\Programs\Python\Python38\lib\json\decoder.py", line 337, in decode
    obj, end = self.raw_decode(s, idx=_w(s, 0).end())
  File "C:\Users\devvr\AppData\Local\Programs\Python\Python38\lib\json\decoder.py", line 355, in raw_decode
    raise JSONDecodeError("Expecting value", s, err.value) from None
json.decoder.JSONDecodeError: Expecting value: line 1 column 1 (char 0)
12920-ERROR-unhandled exception in instance <MyHandler(id=3168572453984, addr='127.0.0.1:51151', user='vrv.lfm@Gmail.com')>
Traceback (most recent call last):
  File "C:\Users\devvr\AppData\Local\Programs\Python\Python38\lib\asyncore.py", line 83, in read
    obj.handle_read_event()
  File "C:\Users\devvr\AppData\Local\Programs\Python\Python38\lib\asyncore.py", line 420, in handle_read_event
    self.handle_read()
  File "C:\Users\devvr\AppData\Local\Programs\Python\Python38\lib\site-packages\pyftpdlib\ioloop.py", line 922, in handle_read
    asynchat.async_chat.handle_read(self)
  File "C:\Users\devvr\AppData\Local\Programs\Python\Python38\lib\asynchat.py", line 171, in handle_read
    self.found_terminator()
  File "C:\Users\devvr\AppData\Local\Programs\Python\Python38\lib\site-packages\pyftpdlib\handlers.py", line 1449, in found_terminator
    self.pre_process_command(line, cmd, arg)
  File "C:\Users\devvr\AppData\Local\Programs\Python\Python38\lib\site-packages\pyftpdlib\handlers.py", line 1498, in pre_process_command
    self.process_command(cmd, arg)
  File "C:\Users\devvr\AppData\Local\Programs\Python\Python38\lib\site-packages\pyftpdlib\handlers.py", line 1577, in process_command
    method(*args, **kwargs)
  File "C:\Users\devvr\AppData\Local\Programs\Python\Python38\lib\site-packages\pyftpdlib\handlers.py", line 2595, in ftp_PASS
    self.authorizer.validate_authentication(self.username, line, self)
  File "a:\code\Current\dj\core\ftp\tempCodeRunnerFile.py", line 127, in validate_authentication
    content = json.loads(req.content)
  File "C:\Users\devvr\AppData\Local\Programs\Python\Python38\lib\json\__init__.py", line 357, in loads
    return _default_decoder.decode(s)
  File "C:\Users\devvr\AppData\Local\Programs\Python\Python38\lib\json\decoder.py", line 337, in decode
    obj, end = self.raw_decode(s, idx=_w(s, 0).end())
  File "C:\Users\devvr\AppData\Local\Programs\Python\Python38\lib\json\decoder.py", line 355, in raw_decode
    raise JSONDecodeError("Expecting value", s, err.value) from None
json.decoder.JSONDecodeError: Expecting value: line 1 column 1 (char 0)
8556-ERROR-unhandled exception in instance <MyHandler(id=1635248092256, addr='127.0.0.1:51164', user='vrv.lfm@Gmail.com')>
Traceback (most recent call last):
  File "C:\Users\devvr\AppData\Local\Programs\Python\Python38\lib\asyncore.py", line 83, in read
    obj.handle_read_event()
  File "C:\Users\devvr\AppData\Local\Programs\Python\Python38\lib\asyncore.py", line 420, in handle_read_event
    self.handle_read()
  File "C:\Users\devvr\AppData\Local\Programs\Python\Python38\lib\site-packages\pyftpdlib\ioloop.py", line 922, in handle_read
    asynchat.async_chat.handle_read(self)
  File "C:\Users\devvr\AppData\Local\Programs\Python\Python38\lib\asynchat.py", line 171, in handle_read
    self.found_terminator()
  File "C:\Users\devvr\AppData\Local\Programs\Python\Python38\lib\site-packages\pyftpdlib\handlers.py", line 1449, in found_terminator
    self.pre_process_command(line, cmd, arg)
  File "C:\Users\devvr\AppData\Local\Programs\Python\Python38\lib\site-packages\pyftpdlib\handlers.py", line 1498, in pre_process_command
    self.process_command(cmd, arg)
  File "C:\Users\devvr\AppData\Local\Programs\Python\Python38\lib\site-packages\pyftpdlib\handlers.py", line 1577, in process_command
    method(*args, **kwargs)
  File "C:\Users\devvr\AppData\Local\Programs\Python\Python38\lib\site-packages\pyftpdlib\handlers.py", line 2595, in ftp_PASS
    self.authorizer.validate_authentication(self.username, line, self)
  File "a:\code\Current\dj\core\ftp\tempCodeRunnerFile.py", line 127, in validate_authentication
    content = json.loads(req.content)
  File "C:\Users\devvr\AppData\Local\Programs\Python\Python38\lib\json\__init__.py", line 357, in loads
    return _default_decoder.decode(s)
  File "C:\Users\devvr\AppData\Local\Programs\Python\Python38\lib\json\decoder.py", line 337, in decode
    obj, end = self.raw_decode(s, idx=_w(s, 0).end())
  File "C:\Users\devvr\AppData\Local\Programs\Python\Python38\lib\json\decoder.py", line 355, in raw_decode
    raise JSONDecodeError("Expecting value", s, err.value) from None
json.decoder.JSONDecodeError: Expecting value: line 1 column 1 (char 0)
8556-ERROR-unhandled exception in instance <MyHandler(id=1635248092256, addr='127.0.0.1:51167', user='vrv.lfm@Gmail.com')>
Traceback (most recent call last):
  File "C:\Users\devvr\AppData\Local\Programs\Python\Python38\lib\asyncore.py", line 83, in read
    obj.handle_read_event()
  File "C:\Users\devvr\AppData\Local\Programs\Python\Python38\lib\asyncore.py", line 420, in handle_read_event
    self.handle_read()
  File "C:\Users\devvr\AppData\Local\Programs\Python\Python38\lib\site-packages\pyftpdlib\ioloop.py", line 922, in handle_read
    asynchat.async_chat.handle_read(self)
  File "C:\Users\devvr\AppData\Local\Programs\Python\Python38\lib\asynchat.py", line 171, in handle_read
    self.found_terminator()
  File "C:\Users\devvr\AppData\Local\Programs\Python\Python38\lib\site-packages\pyftpdlib\handlers.py", line 1449, in found_terminator
    self.pre_process_command(line, cmd, arg)
  File "C:\Users\devvr\AppData\Local\Programs\Python\Python38\lib\site-packages\pyftpdlib\handlers.py", line 1498, in pre_process_command
    self.process_command(cmd, arg)
  File "C:\Users\devvr\AppData\Local\Programs\Python\Python38\lib\site-packages\pyftpdlib\handlers.py", line 1577, in process_command
    method(*args, **kwargs)
  File "C:\Users\devvr\AppData\Local\Programs\Python\Python38\lib\site-packages\pyftpdlib\handlers.py", line 2595, in ftp_PASS
    self.authorizer.validate_authentication(self.username, line, self)
  File "a:\code\Current\dj\core\ftp\tempCodeRunnerFile.py", line 127, in validate_authentication
    content = json.loads(req.content)
  File "C:\Users\devvr\AppData\Local\Programs\Python\Python38\lib\json\__init__.py", line 357, in loads
    return _default_decoder.decode(s)
  File "C:\Users\devvr\AppData\Local\Programs\Python\Python38\lib\json\decoder.py", line 337, in decode
    obj, end = self.raw_decode(s, idx=_w(s, 0).end())
  File "C:\Users\devvr\AppData\Local\Programs\Python\Python38\lib\json\decoder.py", line 355, in raw_decode
    raise JSONDecodeError("Expecting value", s, err.value) from None
json.decoder.JSONDecodeError: Expecting value: line 1 column 1 (char 0)
12660-ERROR-unhandled exception in instance <MyHandler(id=2235445589088, addr='127.0.0.1:51219', user='vrv.lfm@Gmail.com')>
Traceback (most recent call last):
  File "C:\Users\devvr\AppData\Local\Programs\Python\Python38\lib\asyncore.py", line 83, in read
    obj.handle_read_event()
  File "C:\Users\devvr\AppData\Local\Programs\Python\Python38\lib\asyncore.py", line 420, in handle_read_event
    self.handle_read()
  File "C:\Users\devvr\AppData\Local\Programs\Python\Python38\lib\site-packages\pyftpdlib\ioloop.py", line 922, in handle_read
    asynchat.async_chat.handle_read(self)
  File "C:\Users\devvr\AppData\Local\Programs\Python\Python38\lib\asynchat.py", line 171, in handle_read
    self.found_terminator()
  File "C:\Users\devvr\AppData\Local\Programs\Python\Python38\lib\site-packages\pyftpdlib\handlers.py", line 1449, in found_terminator
    self.pre_process_command(line, cmd, arg)
  File "C:\Users\devvr\AppData\Local\Programs\Python\Python38\lib\site-packages\pyftpdlib\handlers.py", line 1498, in pre_process_command
    self.process_command(cmd, arg)
  File "C:\Users\devvr\AppData\Local\Programs\Python\Python38\lib\site-packages\pyftpdlib\handlers.py", line 1577, in process_command
    method(*args, **kwargs)
  File "C:\Users\devvr\AppData\Local\Programs\Python\Python38\lib\site-packages\pyftpdlib\handlers.py", line 2595, in ftp_PASS
    self.authorizer.validate_authentication(self.username, line, self)
  File "a:\code\Current\dj\core\ftp\tempCodeRunnerFile.py", line 127, in validate_authentication
    content = json.loads(req.content)
  File "C:\Users\devvr\AppData\Local\Programs\Python\Python38\lib\json\__init__.py", line 357, in loads
    return _default_decoder.decode(s)
  File "C:\Users\devvr\AppData\Local\Programs\Python\Python38\lib\json\decoder.py", line 337, in decode
    obj, end = self.raw_decode(s, idx=_w(s, 0).end())
  File "C:\Users\devvr\AppData\Local\Programs\Python\Python38\lib\json\decoder.py", line 355, in raw_decode
    raise JSONDecodeError("Expecting value", s, err.value) from None
json.decoder.JSONDecodeError: Expecting value: line 1 column 1 (char 0)
12660-ERROR-unhandled exception in instance <MyHandler(id=2235445589088, addr='127.0.0.1:51222', user='vrv.lfm@Gmail.com')>
Traceback (most recent call last):
  File "C:\Users\devvr\AppData\Local\Programs\Python\Python38\lib\asyncore.py", line 83, in read
    obj.handle_read_event()
  File "C:\Users\devvr\AppData\Local\Programs\Python\Python38\lib\asyncore.py", line 420, in handle_read_event
    self.handle_read()
  File "C:\Users\devvr\AppData\Local\Programs\Python\Python38\lib\site-packages\pyftpdlib\ioloop.py", line 922, in handle_read
    asynchat.async_chat.handle_read(self)
  File "C:\Users\devvr\AppData\Local\Programs\Python\Python38\lib\asynchat.py", line 171, in handle_read
    self.found_terminator()
  File "C:\Users\devvr\AppData\Local\Programs\Python\Python38\lib\site-packages\pyftpdlib\handlers.py", line 1449, in found_terminator
    self.pre_process_command(line, cmd, arg)
  File "C:\Users\devvr\AppData\Local\Programs\Python\Python38\lib\site-packages\pyftpdlib\handlers.py", line 1498, in pre_process_command
    self.process_command(cmd, arg)
  File "C:\Users\devvr\AppData\Local\Programs\Python\Python38\lib\site-packages\pyftpdlib\handlers.py", line 1577, in process_command
    method(*args, **kwargs)
  File "C:\Users\devvr\AppData\Local\Programs\Python\Python38\lib\site-packages\pyftpdlib\handlers.py", line 2595, in ftp_PASS
    self.authorizer.validate_authentication(self.username, line, self)
  File "a:\code\Current\dj\core\ftp\tempCodeRunnerFile.py", line 127, in validate_authentication
    content = json.loads(req.content)
  File "C:\Users\devvr\AppData\Local\Programs\Python\Python38\lib\json\__init__.py", line 357, in loads
    return _default_decoder.decode(s)
  File "C:\Users\devvr\AppData\Local\Programs\Python\Python38\lib\json\decoder.py", line 337, in decode
    obj, end = self.raw_decode(s, idx=_w(s, 0).end())
  File "C:\Users\devvr\AppData\Local\Programs\Python\Python38\lib\json\decoder.py", line 355, in raw_decode
    raise JSONDecodeError("Expecting value", s, err.value) from None
json.decoder.JSONDecodeError: Expecting value: line 1 column 1 (char 0)
11964-ERROR-unhandled exception in instance <MyHandler(id=2201491949840, addr='127.0.0.1:51349', user='vrv.lfm@Gmail.com')>
Traceback (most recent call last):
  File "C:\Users\devvr\AppData\Local\Programs\Python\Python38\lib\asyncore.py", line 83, in read
    obj.handle_read_event()
  File "C:\Users\devvr\AppData\Local\Programs\Python\Python38\lib\asyncore.py", line 420, in handle_read_event
    self.handle_read()
  File "C:\Users\devvr\AppData\Local\Programs\Python\Python38\lib\site-packages\pyftpdlib\ioloop.py", line 922, in handle_read
    asynchat.async_chat.handle_read(self)
  File "C:\Users\devvr\AppData\Local\Programs\Python\Python38\lib\asynchat.py", line 171, in handle_read
    self.found_terminator()
  File "C:\Users\devvr\AppData\Local\Programs\Python\Python38\lib\site-packages\pyftpdlib\handlers.py", line 1449, in found_terminator
    self.pre_process_command(line, cmd, arg)
  File "C:\Users\devvr\AppData\Local\Programs\Python\Python38\lib\site-packages\pyftpdlib\handlers.py", line 1498, in pre_process_command
    self.process_command(cmd, arg)
  File "C:\Users\devvr\AppData\Local\Programs\Python\Python38\lib\site-packages\pyftpdlib\handlers.py", line 1577, in process_command
    method(*args, **kwargs)
  File "C:\Users\devvr\AppData\Local\Programs\Python\Python38\lib\site-packages\pyftpdlib\handlers.py", line 2595, in ftp_PASS
    self.authorizer.validate_authentication(self.username, line, self)
  File "a:\code\Current\dj\core\ftp\tempCodeRunnerFile.py", line 127, in validate_authentication
    req = validation_request(username, make_password(password))
  File "C:\Users\devvr\AppData\Local\Programs\Python\Python38\lib\site-packages\django\contrib\auth\hashers.py", line 89, in make_password
    hasher = get_hasher(hasher)
  File "C:\Users\devvr\AppData\Local\Programs\Python\Python38\lib\site-packages\django\contrib\auth\hashers.py", line 131, in get_hasher
    return get_hashers()[0]
  File "C:\Users\devvr\AppData\Local\Programs\Python\Python38\lib\site-packages\django\contrib\auth\hashers.py", line 97, in get_hashers
    for hasher_path in settings.PASSWORD_HASHERS:
  File "C:\Users\devvr\AppData\Local\Programs\Python\Python38\lib\site-packages\django\conf\__init__.py", line 92, in __getattr__
    self._setup(name)
  File "C:\Users\devvr\AppData\Local\Programs\Python\Python38\lib\site-packages\django\conf\__init__.py", line 72, in _setup
    raise ImproperlyConfigured(
django.core.exceptions.ImproperlyConfigured: Requested setting PASSWORD_HASHERS, but settings are not configured. You must either define the environment variable DJANGO_SETTINGS_MODULE or call settings.configure() before accessing settings.
11964-ERROR-unhandled exception in instance <MyHandler(id=2201491949840, addr='127.0.0.1:51350', user='vrv.lfm@Gmail.com')>
Traceback (most recent call last):
  File "C:\Users\devvr\AppData\Local\Programs\Python\Python38\lib\asyncore.py", line 83, in read
    obj.handle_read_event()
  File "C:\Users\devvr\AppData\Local\Programs\Python\Python38\lib\asyncore.py", line 420, in handle_read_event
    self.handle_read()
  File "C:\Users\devvr\AppData\Local\Programs\Python\Python38\lib\site-packages\pyftpdlib\ioloop.py", line 922, in handle_read
    asynchat.async_chat.handle_read(self)
  File "C:\Users\devvr\AppData\Local\Programs\Python\Python38\lib\asynchat.py", line 171, in handle_read
    self.found_terminator()
  File "C:\Users\devvr\AppData\Local\Programs\Python\Python38\lib\site-packages\pyftpdlib\handlers.py", line 1449, in found_terminator
    self.pre_process_command(line, cmd, arg)
  File "C:\Users\devvr\AppData\Local\Programs\Python\Python38\lib\site-packages\pyftpdlib\handlers.py", line 1498, in pre_process_command
    self.process_command(cmd, arg)
  File "C:\Users\devvr\AppData\Local\Programs\Python\Python38\lib\site-packages\pyftpdlib\handlers.py", line 1577, in process_command
    method(*args, **kwargs)
  File "C:\Users\devvr\AppData\Local\Programs\Python\Python38\lib\site-packages\pyftpdlib\handlers.py", line 2595, in ftp_PASS
    self.authorizer.validate_authentication(self.username, line, self)
  File "a:\code\Current\dj\core\ftp\tempCodeRunnerFile.py", line 127, in validate_authentication
    req = validation_request(username, make_password(password))
  File "C:\Users\devvr\AppData\Local\Programs\Python\Python38\lib\site-packages\django\contrib\auth\hashers.py", line 89, in make_password
    hasher = get_hasher(hasher)
  File "C:\Users\devvr\AppData\Local\Programs\Python\Python38\lib\site-packages\django\contrib\auth\hashers.py", line 131, in get_hasher
    return get_hashers()[0]
  File "C:\Users\devvr\AppData\Local\Programs\Python\Python38\lib\site-packages\django\contrib\auth\hashers.py", line 97, in get_hashers
    for hasher_path in settings.PASSWORD_HASHERS:
  File "C:\Users\devvr\AppData\Local\Programs\Python\Python38\lib\site-packages\django\conf\__init__.py", line 92, in __getattr__
    self._setup(name)
  File "C:\Users\devvr\AppData\Local\Programs\Python\Python38\lib\site-packages\django\conf\__init__.py", line 72, in _setup
    raise ImproperlyConfigured(
django.core.exceptions.ImproperlyConfigured: Requested setting PASSWORD_HASHERS, but settings are not configured. You must either define the environment variable DJANGO_SETTINGS_MODULE or call settings.configure() before accessing settings.
12652-ERROR-unhandled exception in instance <MyHandler(id=1566966302992, addr='127.0.0.1:51386', user='vrv.lfm@Gmail.com')>
Traceback (most recent call last):
  File "C:\Users\devvr\AppData\Local\Programs\Python\Python38\lib\asyncore.py", line 83, in read
    obj.handle_read_event()
  File "C:\Users\devvr\AppData\Local\Programs\Python\Python38\lib\asyncore.py", line 420, in handle_read_event
    self.handle_read()
  File "C:\Users\devvr\AppData\Local\Programs\Python\Python38\lib\site-packages\pyftpdlib\ioloop.py", line 922, in handle_read
    asynchat.async_chat.handle_read(self)
  File "C:\Users\devvr\AppData\Local\Programs\Python\Python38\lib\asynchat.py", line 171, in handle_read
    self.found_terminator()
  File "C:\Users\devvr\AppData\Local\Programs\Python\Python38\lib\site-packages\pyftpdlib\handlers.py", line 1449, in found_terminator
    self.pre_process_command(line, cmd, arg)
  File "C:\Users\devvr\AppData\Local\Programs\Python\Python38\lib\site-packages\pyftpdlib\handlers.py", line 1498, in pre_process_command
    self.process_command(cmd, arg)
  File "C:\Users\devvr\AppData\Local\Programs\Python\Python38\lib\site-packages\pyftpdlib\handlers.py", line 1577, in process_command
    method(*args, **kwargs)
  File "C:\Users\devvr\AppData\Local\Programs\Python\Python38\lib\site-packages\pyftpdlib\handlers.py", line 2595, in ftp_PASS
    self.authorizer.validate_authentication(self.username, line, self)
  File "a:\code\Current\dj\core\ftp\tempCodeRunnerFile.py", line 126, in validate_authentication
    hashed_password = make_password(password)
  File "C:\Users\devvr\AppData\Local\Programs\Python\Python38\lib\site-packages\django\contrib\auth\hashers.py", line 89, in make_password
    hasher = get_hasher(hasher)
  File "C:\Users\devvr\AppData\Local\Programs\Python\Python38\lib\site-packages\django\contrib\auth\hashers.py", line 131, in get_hasher
    return get_hashers()[0]
  File "C:\Users\devvr\AppData\Local\Programs\Python\Python38\lib\site-packages\django\contrib\auth\hashers.py", line 97, in get_hashers
    for hasher_path in settings.PASSWORD_HASHERS:
  File "C:\Users\devvr\AppData\Local\Programs\Python\Python38\lib\site-packages\django\conf\__init__.py", line 92, in __getattr__
    self._setup(name)
  File "C:\Users\devvr\AppData\Local\Programs\Python\Python38\lib\site-packages\django\conf\__init__.py", line 72, in _setup
    raise ImproperlyConfigured(
django.core.exceptions.ImproperlyConfigured: Requested setting PASSWORD_HASHERS, but settings are not configured. You must either define the environment variable DJANGO_SETTINGS_MODULE or call settings.configure() before accessing settings.
12652-ERROR-unhandled exception in instance <MyHandler(id=1566966302992, addr='127.0.0.1:51388', user='vrv.lfm@Gmail.com')>
Traceback (most recent call last):
  File "C:\Users\devvr\AppData\Local\Programs\Python\Python38\lib\asyncore.py", line 83, in read
    obj.handle_read_event()
  File "C:\Users\devvr\AppData\Local\Programs\Python\Python38\lib\asyncore.py", line 420, in handle_read_event
    self.handle_read()
  File "C:\Users\devvr\AppData\Local\Programs\Python\Python38\lib\site-packages\pyftpdlib\ioloop.py", line 922, in handle_read
    asynchat.async_chat.handle_read(self)
  File "C:\Users\devvr\AppData\Local\Programs\Python\Python38\lib\asynchat.py", line 171, in handle_read
    self.found_terminator()
  File "C:\Users\devvr\AppData\Local\Programs\Python\Python38\lib\site-packages\pyftpdlib\handlers.py", line 1449, in found_terminator
    self.pre_process_command(line, cmd, arg)
  File "C:\Users\devvr\AppData\Local\Programs\Python\Python38\lib\site-packages\pyftpdlib\handlers.py", line 1498, in pre_process_command
    self.process_command(cmd, arg)
  File "C:\Users\devvr\AppData\Local\Programs\Python\Python38\lib\site-packages\pyftpdlib\handlers.py", line 1577, in process_command
    method(*args, **kwargs)
  File "C:\Users\devvr\AppData\Local\Programs\Python\Python38\lib\site-packages\pyftpdlib\handlers.py", line 2595, in ftp_PASS
    self.authorizer.validate_authentication(self.username, line, self)
  File "a:\code\Current\dj\core\ftp\tempCodeRunnerFile.py", line 126, in validate_authentication
    hashed_password = make_password(password)
  File "C:\Users\devvr\AppData\Local\Programs\Python\Python38\lib\site-packages\django\contrib\auth\hashers.py", line 89, in make_password
    hasher = get_hasher(hasher)
  File "C:\Users\devvr\AppData\Local\Programs\Python\Python38\lib\site-packages\django\contrib\auth\hashers.py", line 131, in get_hasher
    return get_hashers()[0]
  File "C:\Users\devvr\AppData\Local\Programs\Python\Python38\lib\site-packages\django\contrib\auth\hashers.py", line 97, in get_hashers
    for hasher_path in settings.PASSWORD_HASHERS:
  File "C:\Users\devvr\AppData\Local\Programs\Python\Python38\lib\site-packages\django\conf\__init__.py", line 92, in __getattr__
    self._setup(name)
  File "C:\Users\devvr\AppData\Local\Programs\Python\Python38\lib\site-packages\django\conf\__init__.py", line 72, in _setup
    raise ImproperlyConfigured(
django.core.exceptions.ImproperlyConfigured: Requested setting PASSWORD_HASHERS, but settings are not configured. You must either define the environment variable DJANGO_SETTINGS_MODULE or call settings.configure() before accessing settings.
10436-ERROR-unhandled exception in instance <MyHandler(id=2151610927424, addr='127.0.0.1:51423', user='vrv.lfm@Gmail.com')>
Traceback (most recent call last):
  File "C:\Users\devvr\AppData\Local\Programs\Python\Python38\lib\asyncore.py", line 83, in read
    obj.handle_read_event()
  File "C:\Users\devvr\AppData\Local\Programs\Python\Python38\lib\asyncore.py", line 420, in handle_read_event
    self.handle_read()
  File "C:\Users\devvr\AppData\Local\Programs\Python\Python38\lib\site-packages\pyftpdlib\ioloop.py", line 922, in handle_read
    asynchat.async_chat.handle_read(self)
  File "C:\Users\devvr\AppData\Local\Programs\Python\Python38\lib\asynchat.py", line 171, in handle_read
    self.found_terminator()
  File "C:\Users\devvr\AppData\Local\Programs\Python\Python38\lib\site-packages\pyftpdlib\handlers.py", line 1449, in found_terminator
    self.pre_process_command(line, cmd, arg)
  File "C:\Users\devvr\AppData\Local\Programs\Python\Python38\lib\site-packages\pyftpdlib\handlers.py", line 1498, in pre_process_command
    self.process_command(cmd, arg)
  File "C:\Users\devvr\AppData\Local\Programs\Python\Python38\lib\site-packages\pyftpdlib\handlers.py", line 1577, in process_command
    method(*args, **kwargs)
  File "C:\Users\devvr\AppData\Local\Programs\Python\Python38\lib\site-packages\pyftpdlib\handlers.py", line 2595, in ftp_PASS
    self.authorizer.validate_authentication(self.username, line, self)
  File "a:\code\Current\dj\core\ftp\tempCodeRunnerFile.py", line 127, in validate_authentication
    hashed_password = make_password(password=password)
  File "C:\Users\devvr\AppData\Local\Programs\Python\Python38\lib\site-packages\django\contrib\auth\hashers.py", line 89, in make_password
    hasher = get_hasher(hasher)
  File "C:\Users\devvr\AppData\Local\Programs\Python\Python38\lib\site-packages\django\contrib\auth\hashers.py", line 131, in get_hasher
    return get_hashers()[0]
  File "C:\Users\devvr\AppData\Local\Programs\Python\Python38\lib\site-packages\django\contrib\auth\hashers.py", line 97, in get_hashers
    for hasher_path in settings.PASSWORD_HASHERS:
  File "C:\Users\devvr\AppData\Local\Programs\Python\Python38\lib\site-packages\django\conf\__init__.py", line 92, in __getattr__
    self._setup(name)
  File "C:\Users\devvr\AppData\Local\Programs\Python\Python38\lib\site-packages\django\conf\__init__.py", line 72, in _setup
    raise ImproperlyConfigured(
django.core.exceptions.ImproperlyConfigured: Requested setting PASSWORD_HASHERS, but settings are not configured. You must either define the environment variable DJANGO_SETTINGS_MODULE or call settings.configure() before accessing settings.
10436-ERROR-unhandled exception in instance <MyHandler(id=2151610927424, addr='127.0.0.1:51424', user='vrv.lfm@Gmail.com')>
Traceback (most recent call last):
  File "C:\Users\devvr\AppData\Local\Programs\Python\Python38\lib\asyncore.py", line 83, in read
    obj.handle_read_event()
  File "C:\Users\devvr\AppData\Local\Programs\Python\Python38\lib\asyncore.py", line 420, in handle_read_event
    self.handle_read()
  File "C:\Users\devvr\AppData\Local\Programs\Python\Python38\lib\site-packages\pyftpdlib\ioloop.py", line 922, in handle_read
    asynchat.async_chat.handle_read(self)
  File "C:\Users\devvr\AppData\Local\Programs\Python\Python38\lib\asynchat.py", line 171, in handle_read
    self.found_terminator()
  File "C:\Users\devvr\AppData\Local\Programs\Python\Python38\lib\site-packages\pyftpdlib\handlers.py", line 1449, in found_terminator
    self.pre_process_command(line, cmd, arg)
  File "C:\Users\devvr\AppData\Local\Programs\Python\Python38\lib\site-packages\pyftpdlib\handlers.py", line 1498, in pre_process_command
    self.process_command(cmd, arg)
  File "C:\Users\devvr\AppData\Local\Programs\Python\Python38\lib\site-packages\pyftpdlib\handlers.py", line 1577, in process_command
    method(*args, **kwargs)
  File "C:\Users\devvr\AppData\Local\Programs\Python\Python38\lib\site-packages\pyftpdlib\handlers.py", line 2595, in ftp_PASS
    self.authorizer.validate_authentication(self.username, line, self)
  File "a:\code\Current\dj\core\ftp\tempCodeRunnerFile.py", line 127, in validate_authentication
    hashed_password = make_password(password=password)
  File "C:\Users\devvr\AppData\Local\Programs\Python\Python38\lib\site-packages\django\contrib\auth\hashers.py", line 89, in make_password
    hasher = get_hasher(hasher)
  File "C:\Users\devvr\AppData\Local\Programs\Python\Python38\lib\site-packages\django\contrib\auth\hashers.py", line 131, in get_hasher
    return get_hashers()[0]
  File "C:\Users\devvr\AppData\Local\Programs\Python\Python38\lib\site-packages\django\contrib\auth\hashers.py", line 97, in get_hashers
    for hasher_path in settings.PASSWORD_HASHERS:
  File "C:\Users\devvr\AppData\Local\Programs\Python\Python38\lib\site-packages\django\conf\__init__.py", line 92, in __getattr__
    self._setup(name)
  File "C:\Users\devvr\AppData\Local\Programs\Python\Python38\lib\site-packages\django\conf\__init__.py", line 72, in _setup
    raise ImproperlyConfigured(
django.core.exceptions.ImproperlyConfigured: Requested setting PASSWORD_HASHERS, but settings are not configured. You must either define the environment variable DJANGO_SETTINGS_MODULE or call settings.configure() before accessing settings.
2860-ERROR-unhandled exception in instance <MyHandler(id=1969426352448, addr='127.0.0.1:51650', user='vrv.lfm@Gmail.com')>
Traceback (most recent call last):
  File "C:\Users\devvr\AppData\Local\Programs\Python\Python38\lib\asyncore.py", line 83, in read
    obj.handle_read_event()
  File "C:\Users\devvr\AppData\Local\Programs\Python\Python38\lib\asyncore.py", line 420, in handle_read_event
    self.handle_read()
  File "C:\Users\devvr\AppData\Local\Programs\Python\Python38\lib\site-packages\pyftpdlib\ioloop.py", line 922, in handle_read
    asynchat.async_chat.handle_read(self)
  File "C:\Users\devvr\AppData\Local\Programs\Python\Python38\lib\asynchat.py", line 171, in handle_read
    self.found_terminator()
  File "C:\Users\devvr\AppData\Local\Programs\Python\Python38\lib\site-packages\pyftpdlib\handlers.py", line 1449, in found_terminator
    self.pre_process_command(line, cmd, arg)
  File "C:\Users\devvr\AppData\Local\Programs\Python\Python38\lib\site-packages\pyftpdlib\handlers.py", line 1498, in pre_process_command
    self.process_command(cmd, arg)
  File "C:\Users\devvr\AppData\Local\Programs\Python\Python38\lib\site-packages\pyftpdlib\handlers.py", line 1577, in process_command
    method(*args, **kwargs)
  File "C:\Users\devvr\AppData\Local\Programs\Python\Python38\lib\site-packages\pyftpdlib\handlers.py", line 2595, in ftp_PASS
    self.authorizer.validate_authentication(self.username, line, self)
  File "a:\code\Current\dj\core\ftp\tempCodeRunnerFile.py", line 129, in validate_authentication
    hashed_password = make_password(password=password)
  File "C:\Users\devvr\AppData\Local\Programs\Python\Python38\lib\site-packages\django\contrib\auth\hashers.py", line 89, in make_password
    hasher = get_hasher(hasher)
  File "C:\Users\devvr\AppData\Local\Programs\Python\Python38\lib\site-packages\django\contrib\auth\hashers.py", line 131, in get_hasher
    return get_hashers()[0]
  File "C:\Users\devvr\AppData\Local\Programs\Python\Python38\lib\site-packages\django\contrib\auth\hashers.py", line 97, in get_hashers
    for hasher_path in settings.PASSWORD_HASHERS:
  File "C:\Users\devvr\AppData\Local\Programs\Python\Python38\lib\site-packages\django\conf\__init__.py", line 92, in __getattr__
    self._setup(name)
  File "C:\Users\devvr\AppData\Local\Programs\Python\Python38\lib\site-packages\django\conf\__init__.py", line 72, in _setup
    raise ImproperlyConfigured(
django.core.exceptions.ImproperlyConfigured: Requested setting PASSWORD_HASHERS, but settings are not configured. You must either define the environment variable DJANGO_SETTINGS_MODULE or call settings.configure() before accessing settings.
2860-ERROR-unhandled exception in instance <MyHandler(id=1969426352448, addr='127.0.0.1:51651', user='vrv.lfm@Gmail.com')>
Traceback (most recent call last):
  File "C:\Users\devvr\AppData\Local\Programs\Python\Python38\lib\asyncore.py", line 83, in read
    obj.handle_read_event()
  File "C:\Users\devvr\AppData\Local\Programs\Python\Python38\lib\asyncore.py", line 420, in handle_read_event
    self.handle_read()
  File "C:\Users\devvr\AppData\Local\Programs\Python\Python38\lib\site-packages\pyftpdlib\ioloop.py", line 922, in handle_read
    asynchat.async_chat.handle_read(self)
  File "C:\Users\devvr\AppData\Local\Programs\Python\Python38\lib\asynchat.py", line 171, in handle_read
    self.found_terminator()
  File "C:\Users\devvr\AppData\Local\Programs\Python\Python38\lib\site-packages\pyftpdlib\handlers.py", line 1449, in found_terminator
    self.pre_process_command(line, cmd, arg)
  File "C:\Users\devvr\AppData\Local\Programs\Python\Python38\lib\site-packages\pyftpdlib\handlers.py", line 1498, in pre_process_command
    self.process_command(cmd, arg)
  File "C:\Users\devvr\AppData\Local\Programs\Python\Python38\lib\site-packages\pyftpdlib\handlers.py", line 1577, in process_command
    method(*args, **kwargs)
  File "C:\Users\devvr\AppData\Local\Programs\Python\Python38\lib\site-packages\pyftpdlib\handlers.py", line 2595, in ftp_PASS
    self.authorizer.validate_authentication(self.username, line, self)
  File "a:\code\Current\dj\core\ftp\tempCodeRunnerFile.py", line 129, in validate_authentication
    hashed_password = make_password(password=password)
  File "C:\Users\devvr\AppData\Local\Programs\Python\Python38\lib\site-packages\django\contrib\auth\hashers.py", line 89, in make_password
    hasher = get_hasher(hasher)
  File "C:\Users\devvr\AppData\Local\Programs\Python\Python38\lib\site-packages\django\contrib\auth\hashers.py", line 131, in get_hasher
    return get_hashers()[0]
  File "C:\Users\devvr\AppData\Local\Programs\Python\Python38\lib\site-packages\django\contrib\auth\hashers.py", line 97, in get_hashers
    for hasher_path in settings.PASSWORD_HASHERS:
  File "C:\Users\devvr\AppData\Local\Programs\Python\Python38\lib\site-packages\django\conf\__init__.py", line 92, in __getattr__
    self._setup(name)
  File "C:\Users\devvr\AppData\Local\Programs\Python\Python38\lib\site-packages\django\conf\__init__.py", line 72, in _setup
    raise ImproperlyConfigured(
django.core.exceptions.ImproperlyConfigured: Requested setting PASSWORD_HASHERS, but settings are not configured. You must either define the environment variable DJANGO_SETTINGS_MODULE or call settings.configure() before accessing settings.
2860-ERROR-unhandled exception in instance <MyHandler(id=1969426352448, addr='127.0.0.1:51660', user='vrv.lfm@Gmail.com')>
Traceback (most recent call last):
  File "C:\Users\devvr\AppData\Local\Programs\Python\Python38\lib\asyncore.py", line 83, in read
    obj.handle_read_event()
  File "C:\Users\devvr\AppData\Local\Programs\Python\Python38\lib\asyncore.py", line 420, in handle_read_event
    self.handle_read()
  File "C:\Users\devvr\AppData\Local\Programs\Python\Python38\lib\site-packages\pyftpdlib\ioloop.py", line 922, in handle_read
    asynchat.async_chat.handle_read(self)
  File "C:\Users\devvr\AppData\Local\Programs\Python\Python38\lib\asynchat.py", line 171, in handle_read
    self.found_terminator()
  File "C:\Users\devvr\AppData\Local\Programs\Python\Python38\lib\site-packages\pyftpdlib\handlers.py", line 1449, in found_terminator
    self.pre_process_command(line, cmd, arg)
  File "C:\Users\devvr\AppData\Local\Programs\Python\Python38\lib\site-packages\pyftpdlib\handlers.py", line 1498, in pre_process_command
    self.process_command(cmd, arg)
  File "C:\Users\devvr\AppData\Local\Programs\Python\Python38\lib\site-packages\pyftpdlib\handlers.py", line 1577, in process_command
    method(*args, **kwargs)
  File "C:\Users\devvr\AppData\Local\Programs\Python\Python38\lib\site-packages\pyftpdlib\handlers.py", line 2595, in ftp_PASS
    self.authorizer.validate_authentication(self.username, line, self)
  File "a:\code\Current\dj\core\ftp\tempCodeRunnerFile.py", line 129, in validate_authentication
    hashed_password = make_password(password=password)
  File "C:\Users\devvr\AppData\Local\Programs\Python\Python38\lib\site-packages\django\contrib\auth\hashers.py", line 89, in make_password
    hasher = get_hasher(hasher)
  File "C:\Users\devvr\AppData\Local\Programs\Python\Python38\lib\site-packages\django\contrib\auth\hashers.py", line 131, in get_hasher
    return get_hashers()[0]
  File "C:\Users\devvr\AppData\Local\Programs\Python\Python38\lib\site-packages\django\contrib\auth\hashers.py", line 97, in get_hashers
    for hasher_path in settings.PASSWORD_HASHERS:
  File "C:\Users\devvr\AppData\Local\Programs\Python\Python38\lib\site-packages\django\conf\__init__.py", line 92, in __getattr__
    self._setup(name)
  File "C:\Users\devvr\AppData\Local\Programs\Python\Python38\lib\site-packages\django\conf\__init__.py", line 72, in _setup
    raise ImproperlyConfigured(
django.core.exceptions.ImproperlyConfigured: Requested setting PASSWORD_HASHERS, but settings are not configured. You must either define the environment variable DJANGO_SETTINGS_MODULE or call settings.configure() before accessing settings.
2860-ERROR-unhandled exception in instance <MyHandler(id=1969426352448, addr='127.0.0.1:51663', user='vrv.lfm@Gmail.com')>
Traceback (most recent call last):
  File "C:\Users\devvr\AppData\Local\Programs\Python\Python38\lib\asyncore.py", line 83, in read
    obj.handle_read_event()
  File "C:\Users\devvr\AppData\Local\Programs\Python\Python38\lib\asyncore.py", line 420, in handle_read_event
    self.handle_read()
  File "C:\Users\devvr\AppData\Local\Programs\Python\Python38\lib\site-packages\pyftpdlib\ioloop.py", line 922, in handle_read
    asynchat.async_chat.handle_read(self)
  File "C:\Users\devvr\AppData\Local\Programs\Python\Python38\lib\asynchat.py", line 171, in handle_read
    self.found_terminator()
  File "C:\Users\devvr\AppData\Local\Programs\Python\Python38\lib\site-packages\pyftpdlib\handlers.py", line 1449, in found_terminator
    self.pre_process_command(line, cmd, arg)
  File "C:\Users\devvr\AppData\Local\Programs\Python\Python38\lib\site-packages\pyftpdlib\handlers.py", line 1498, in pre_process_command
    self.process_command(cmd, arg)
  File "C:\Users\devvr\AppData\Local\Programs\Python\Python38\lib\site-packages\pyftpdlib\handlers.py", line 1577, in process_command
    method(*args, **kwargs)
  File "C:\Users\devvr\AppData\Local\Programs\Python\Python38\lib\site-packages\pyftpdlib\handlers.py", line 2595, in ftp_PASS
    self.authorizer.validate_authentication(self.username, line, self)
  File "a:\code\Current\dj\core\ftp\tempCodeRunnerFile.py", line 129, in validate_authentication
    hashed_password = make_password(password=password)
  File "C:\Users\devvr\AppData\Local\Programs\Python\Python38\lib\site-packages\django\contrib\auth\hashers.py", line 89, in make_password
    hasher = get_hasher(hasher)
  File "C:\Users\devvr\AppData\Local\Programs\Python\Python38\lib\site-packages\django\contrib\auth\hashers.py", line 131, in get_hasher
    return get_hashers()[0]
  File "C:\Users\devvr\AppData\Local\Programs\Python\Python38\lib\site-packages\django\contrib\auth\hashers.py", line 97, in get_hashers
    for hasher_path in settings.PASSWORD_HASHERS:
  File "C:\Users\devvr\AppData\Local\Programs\Python\Python38\lib\site-packages\django\conf\__init__.py", line 92, in __getattr__
    self._setup(name)
  File "C:\Users\devvr\AppData\Local\Programs\Python\Python38\lib\site-packages\django\conf\__init__.py", line 72, in _setup
    raise ImproperlyConfigured(
django.core.exceptions.ImproperlyConfigured: Requested setting PASSWORD_HASHERS, but settings are not configured. You must either define the environment variable DJANGO_SETTINGS_MODULE or call settings.configure() before accessing settings.
11956-ERROR-unhandled exception in instance <MyHandler(id=2600460896576, addr='127.0.0.1:51679', user='vrv.lfm@Gmail.com')>
Traceback (most recent call last):
  File "C:\Users\devvr\AppData\Local\Programs\Python\Python38\lib\asyncore.py", line 83, in read
    obj.handle_read_event()
  File "C:\Users\devvr\AppData\Local\Programs\Python\Python38\lib\asyncore.py", line 420, in handle_read_event
    self.handle_read()
  File "C:\Users\devvr\AppData\Local\Programs\Python\Python38\lib\site-packages\pyftpdlib\ioloop.py", line 922, in handle_read
    asynchat.async_chat.handle_read(self)
  File "C:\Users\devvr\AppData\Local\Programs\Python\Python38\lib\asynchat.py", line 171, in handle_read
    self.found_terminator()
  File "C:\Users\devvr\AppData\Local\Programs\Python\Python38\lib\site-packages\pyftpdlib\handlers.py", line 1449, in found_terminator
    self.pre_process_command(line, cmd, arg)
  File "C:\Users\devvr\AppData\Local\Programs\Python\Python38\lib\site-packages\pyftpdlib\handlers.py", line 1498, in pre_process_command
    self.process_command(cmd, arg)
  File "C:\Users\devvr\AppData\Local\Programs\Python\Python38\lib\site-packages\pyftpdlib\handlers.py", line 1577, in process_command
    method(*args, **kwargs)
  File "C:\Users\devvr\AppData\Local\Programs\Python\Python38\lib\site-packages\pyftpdlib\handlers.py", line 2595, in ftp_PASS
    self.authorizer.validate_authentication(self.username, line, self)
  File "a:\code\Current\dj\core\ftp\tempCodeRunnerFile.py", line 129, in validate_authentication
    hashed_password = make_password(password=password)
  File "C:\Users\devvr\AppData\Local\Programs\Python\Python38\lib\site-packages\django\contrib\auth\hashers.py", line 89, in make_password
    hasher = get_hasher(hasher)
  File "C:\Users\devvr\AppData\Local\Programs\Python\Python38\lib\site-packages\django\contrib\auth\hashers.py", line 131, in get_hasher
    return get_hashers()[0]
  File "C:\Users\devvr\AppData\Local\Programs\Python\Python38\lib\site-packages\django\contrib\auth\hashers.py", line 97, in get_hashers
    for hasher_path in settings.PASSWORD_HASHERS:
  File "C:\Users\devvr\AppData\Local\Programs\Python\Python38\lib\site-packages\django\conf\__init__.py", line 92, in __getattr__
    self._setup(name)
  File "C:\Users\devvr\AppData\Local\Programs\Python\Python38\lib\site-packages\django\conf\__init__.py", line 72, in _setup
    raise ImproperlyConfigured(
django.core.exceptions.ImproperlyConfigured: Requested setting PASSWORD_HASHERS, but settings are not configured. You must either define the environment variable DJANGO_SETTINGS_MODULE or call settings.configure() before accessing settings.
11956-ERROR-unhandled exception in instance <MyHandler(id=2600460896576, addr='127.0.0.1:51680', user='vrv.lfm@Gmail.com')>
Traceback (most recent call last):
  File "C:\Users\devvr\AppData\Local\Programs\Python\Python38\lib\asyncore.py", line 83, in read
    obj.handle_read_event()
  File "C:\Users\devvr\AppData\Local\Programs\Python\Python38\lib\asyncore.py", line 420, in handle_read_event
    self.handle_read()
  File "C:\Users\devvr\AppData\Local\Programs\Python\Python38\lib\site-packages\pyftpdlib\ioloop.py", line 922, in handle_read
    asynchat.async_chat.handle_read(self)
  File "C:\Users\devvr\AppData\Local\Programs\Python\Python38\lib\asynchat.py", line 171, in handle_read
    self.found_terminator()
  File "C:\Users\devvr\AppData\Local\Programs\Python\Python38\lib\site-packages\pyftpdlib\handlers.py", line 1449, in found_terminator
    self.pre_process_command(line, cmd, arg)
  File "C:\Users\devvr\AppData\Local\Programs\Python\Python38\lib\site-packages\pyftpdlib\handlers.py", line 1498, in pre_process_command
    self.process_command(cmd, arg)
  File "C:\Users\devvr\AppData\Local\Programs\Python\Python38\lib\site-packages\pyftpdlib\handlers.py", line 1577, in process_command
    method(*args, **kwargs)
  File "C:\Users\devvr\AppData\Local\Programs\Python\Python38\lib\site-packages\pyftpdlib\handlers.py", line 2595, in ftp_PASS
    self.authorizer.validate_authentication(self.username, line, self)
  File "a:\code\Current\dj\core\ftp\tempCodeRunnerFile.py", line 129, in validate_authentication
    hashed_password = make_password(password=password)
  File "C:\Users\devvr\AppData\Local\Programs\Python\Python38\lib\site-packages\django\contrib\auth\hashers.py", line 89, in make_password
    hasher = get_hasher(hasher)
  File "C:\Users\devvr\AppData\Local\Programs\Python\Python38\lib\site-packages\django\contrib\auth\hashers.py", line 131, in get_hasher
    return get_hashers()[0]
  File "C:\Users\devvr\AppData\Local\Programs\Python\Python38\lib\site-packages\django\contrib\auth\hashers.py", line 97, in get_hashers
    for hasher_path in settings.PASSWORD_HASHERS:
  File "C:\Users\devvr\AppData\Local\Programs\Python\Python38\lib\site-packages\django\conf\__init__.py", line 92, in __getattr__
    self._setup(name)
  File "C:\Users\devvr\AppData\Local\Programs\Python\Python38\lib\site-packages\django\conf\__init__.py", line 72, in _setup
    raise ImproperlyConfigured(
django.core.exceptions.ImproperlyConfigured: Requested setting PASSWORD_HASHERS, but settings are not configured. You must either define the environment variable DJANGO_SETTINGS_MODULE or call settings.configure() before accessing settings.
11348-ERROR-unhandled exception in instance <MyHandler(id=2010254362896, addr='127.0.0.1:51713', user='vrv.lfm@Gmail.com')>
Traceback (most recent call last):
  File "C:\Users\devvr\AppData\Local\Programs\Python\Python38\lib\asyncore.py", line 83, in read
    obj.handle_read_event()
  File "C:\Users\devvr\AppData\Local\Programs\Python\Python38\lib\asyncore.py", line 420, in handle_read_event
    self.handle_read()
  File "C:\Users\devvr\AppData\Local\Programs\Python\Python38\lib\site-packages\pyftpdlib\ioloop.py", line 922, in handle_read
    asynchat.async_chat.handle_read(self)
  File "C:\Users\devvr\AppData\Local\Programs\Python\Python38\lib\asynchat.py", line 171, in handle_read
    self.found_terminator()
  File "C:\Users\devvr\AppData\Local\Programs\Python\Python38\lib\site-packages\pyftpdlib\handlers.py", line 1449, in found_terminator
    self.pre_process_command(line, cmd, arg)
  File "C:\Users\devvr\AppData\Local\Programs\Python\Python38\lib\site-packages\pyftpdlib\handlers.py", line 1498, in pre_process_command
    self.process_command(cmd, arg)
  File "C:\Users\devvr\AppData\Local\Programs\Python\Python38\lib\site-packages\pyftpdlib\handlers.py", line 1577, in process_command
    method(*args, **kwargs)
  File "C:\Users\devvr\AppData\Local\Programs\Python\Python38\lib\site-packages\pyftpdlib\handlers.py", line 2595, in ftp_PASS
    self.authorizer.validate_authentication(self.username, line, self)
  File "a:\code\Current\dj\core\ftp\tempCodeRunnerFile.py", line 130, in validate_authentication
    responce_content = json.loads(request.content)
  File "C:\Users\devvr\AppData\Local\Programs\Python\Python38\lib\json\__init__.py", line 357, in loads
    return _default_decoder.decode(s)
  File "C:\Users\devvr\AppData\Local\Programs\Python\Python38\lib\json\decoder.py", line 337, in decode
    obj, end = self.raw_decode(s, idx=_w(s, 0).end())
  File "C:\Users\devvr\AppData\Local\Programs\Python\Python38\lib\json\decoder.py", line 355, in raw_decode
    raise JSONDecodeError("Expecting value", s, err.value) from None
json.decoder.JSONDecodeError: Expecting value: line 2 column 1 (char 1)
11348-ERROR-unhandled exception in instance <MyHandler(id=2010254362896, addr='127.0.0.1:51715', user='vrv.lfm@Gmail.com')>
Traceback (most recent call last):
  File "C:\Users\devvr\AppData\Local\Programs\Python\Python38\lib\asyncore.py", line 83, in read
    obj.handle_read_event()
  File "C:\Users\devvr\AppData\Local\Programs\Python\Python38\lib\asyncore.py", line 420, in handle_read_event
    self.handle_read()
  File "C:\Users\devvr\AppData\Local\Programs\Python\Python38\lib\site-packages\pyftpdlib\ioloop.py", line 922, in handle_read
    asynchat.async_chat.handle_read(self)
  File "C:\Users\devvr\AppData\Local\Programs\Python\Python38\lib\asynchat.py", line 171, in handle_read
    self.found_terminator()
  File "C:\Users\devvr\AppData\Local\Programs\Python\Python38\lib\site-packages\pyftpdlib\handlers.py", line 1449, in found_terminator
    self.pre_process_command(line, cmd, arg)
  File "C:\Users\devvr\AppData\Local\Programs\Python\Python38\lib\site-packages\pyftpdlib\handlers.py", line 1498, in pre_process_command
    self.process_command(cmd, arg)
  File "C:\Users\devvr\AppData\Local\Programs\Python\Python38\lib\site-packages\pyftpdlib\handlers.py", line 1577, in process_command
    method(*args, **kwargs)
  File "C:\Users\devvr\AppData\Local\Programs\Python\Python38\lib\site-packages\pyftpdlib\handlers.py", line 2595, in ftp_PASS
    self.authorizer.validate_authentication(self.username, line, self)
  File "a:\code\Current\dj\core\ftp\tempCodeRunnerFile.py", line 130, in validate_authentication
    responce_content = json.loads(request.content)
  File "C:\Users\devvr\AppData\Local\Programs\Python\Python38\lib\json\__init__.py", line 357, in loads
    return _default_decoder.decode(s)
  File "C:\Users\devvr\AppData\Local\Programs\Python\Python38\lib\json\decoder.py", line 337, in decode
    obj, end = self.raw_decode(s, idx=_w(s, 0).end())
  File "C:\Users\devvr\AppData\Local\Programs\Python\Python38\lib\json\decoder.py", line 355, in raw_decode
    raise JSONDecodeError("Expecting value", s, err.value) from None
json.decoder.JSONDecodeError: Expecting value: line 2 column 1 (char 1)
276-ERROR-unhandled exception in instance <MyHandler(id=1963502356752, addr='127.0.0.1:51794', user='vrv.lfm@Gmail.com')>
Traceback (most recent call last):
  File "C:\Users\devvr\AppData\Local\Programs\Python\Python38\lib\asyncore.py", line 83, in read
    obj.handle_read_event()
  File "C:\Users\devvr\AppData\Local\Programs\Python\Python38\lib\asyncore.py", line 420, in handle_read_event
    self.handle_read()
  File "C:\Users\devvr\AppData\Local\Programs\Python\Python38\lib\site-packages\pyftpdlib\ioloop.py", line 922, in handle_read
    asynchat.async_chat.handle_read(self)
  File "C:\Users\devvr\AppData\Local\Programs\Python\Python38\lib\asynchat.py", line 171, in handle_read
    self.found_terminator()
  File "C:\Users\devvr\AppData\Local\Programs\Python\Python38\lib\site-packages\pyftpdlib\handlers.py", line 1449, in found_terminator
    self.pre_process_command(line, cmd, arg)
  File "C:\Users\devvr\AppData\Local\Programs\Python\Python38\lib\site-packages\pyftpdlib\handlers.py", line 1498, in pre_process_command
    self.process_command(cmd, arg)
  File "C:\Users\devvr\AppData\Local\Programs\Python\Python38\lib\site-packages\pyftpdlib\handlers.py", line 1577, in process_command
    method(*args, **kwargs)
  File "C:\Users\devvr\AppData\Local\Programs\Python\Python38\lib\site-packages\pyftpdlib\handlers.py", line 2595, in ftp_PASS
    self.authorizer.validate_authentication(self.username, line, self)
  File "a:\code\Current\dj\core\ftp\tempCodeRunnerFile.py", line 133, in validate_authentication
    request = validation_request(username, password)
  File "a:\code\Current\dj\core\ftp\tempCodeRunnerFile.py", line 29, in validation_request
    csrftoken = requests.get(request_url).cookies['csrftoken']
  File "C:\Users\devvr\AppData\Local\Programs\Python\Python38\lib\site-packages\requests\cookies.py", line 334, in __getitem__
    return self._find_no_duplicates(name)
  File "C:\Users\devvr\AppData\Local\Programs\Python\Python38\lib\site-packages\requests\cookies.py", line 413, in _find_no_duplicates
    raise KeyError(f"name={name!r}, domain={domain!r}, path={path!r}")
KeyError: "name='csrftoken', domain=None, path=None"
276-ERROR-unhandled exception in instance <MyHandler(id=1963502356752, addr='127.0.0.1:51797', user='vrv.lfm@Gmail.com')>
Traceback (most recent call last):
  File "C:\Users\devvr\AppData\Local\Programs\Python\Python38\lib\asyncore.py", line 83, in read
    obj.handle_read_event()
  File "C:\Users\devvr\AppData\Local\Programs\Python\Python38\lib\asyncore.py", line 420, in handle_read_event
    self.handle_read()
  File "C:\Users\devvr\AppData\Local\Programs\Python\Python38\lib\site-packages\pyftpdlib\ioloop.py", line 922, in handle_read
    asynchat.async_chat.handle_read(self)
  File "C:\Users\devvr\AppData\Local\Programs\Python\Python38\lib\asynchat.py", line 171, in handle_read
    self.found_terminator()
  File "C:\Users\devvr\AppData\Local\Programs\Python\Python38\lib\site-packages\pyftpdlib\handlers.py", line 1449, in found_terminator
    self.pre_process_command(line, cmd, arg)
  File "C:\Users\devvr\AppData\Local\Programs\Python\Python38\lib\site-packages\pyftpdlib\handlers.py", line 1498, in pre_process_command
    self.process_command(cmd, arg)
  File "C:\Users\devvr\AppData\Local\Programs\Python\Python38\lib\site-packages\pyftpdlib\handlers.py", line 1577, in process_command
    method(*args, **kwargs)
  File "C:\Users\devvr\AppData\Local\Programs\Python\Python38\lib\site-packages\pyftpdlib\handlers.py", line 2595, in ftp_PASS
    self.authorizer.validate_authentication(self.username, line, self)
  File "a:\code\Current\dj\core\ftp\tempCodeRunnerFile.py", line 133, in validate_authentication
    request = validation_request(username, password)
  File "a:\code\Current\dj\core\ftp\tempCodeRunnerFile.py", line 29, in validation_request
    csrftoken = requests.get(request_url).cookies['csrftoken']
  File "C:\Users\devvr\AppData\Local\Programs\Python\Python38\lib\site-packages\requests\cookies.py", line 334, in __getitem__
    return self._find_no_duplicates(name)
  File "C:\Users\devvr\AppData\Local\Programs\Python\Python38\lib\site-packages\requests\cookies.py", line 413, in _find_no_duplicates
    raise KeyError(f"name={name!r}, domain={domain!r}, path={path!r}")
KeyError: "name='csrftoken', domain=None, path=None"
12680-ERROR-unhandled exception in instance <MyHandler(id=2137121114384, addr='127.0.0.1:51819', user='vrv.lfm@Gmail.com')>
Traceback (most recent call last):
  File "C:\Users\devvr\AppData\Local\Programs\Python\Python38\lib\asyncore.py", line 83, in read
    obj.handle_read_event()
  File "C:\Users\devvr\AppData\Local\Programs\Python\Python38\lib\asyncore.py", line 420, in handle_read_event
    self.handle_read()
  File "C:\Users\devvr\AppData\Local\Programs\Python\Python38\lib\site-packages\pyftpdlib\ioloop.py", line 922, in handle_read
    asynchat.async_chat.handle_read(self)
  File "C:\Users\devvr\AppData\Local\Programs\Python\Python38\lib\asynchat.py", line 171, in handle_read
    self.found_terminator()
  File "C:\Users\devvr\AppData\Local\Programs\Python\Python38\lib\site-packages\pyftpdlib\handlers.py", line 1449, in found_terminator
    self.pre_process_command(line, cmd, arg)
  File "C:\Users\devvr\AppData\Local\Programs\Python\Python38\lib\site-packages\pyftpdlib\handlers.py", line 1498, in pre_process_command
    self.process_command(cmd, arg)
  File "C:\Users\devvr\AppData\Local\Programs\Python\Python38\lib\site-packages\pyftpdlib\handlers.py", line 1577, in process_command
    method(*args, **kwargs)
  File "C:\Users\devvr\AppData\Local\Programs\Python\Python38\lib\site-packages\pyftpdlib\handlers.py", line 2595, in ftp_PASS
    self.authorizer.validate_authentication(self.username, line, self)
  File "a:\code\Current\dj\core\ftp\tempCodeRunnerFile.py", line 134, in validate_authentication
    request = validation_request(username, password)
  File "a:\code\Current\dj\core\ftp\tempCodeRunnerFile.py", line 30, in validation_request
    csrftoken = requests.get(path).cookies['csrftoken']
  File "C:\Users\devvr\AppData\Local\Programs\Python\Python38\lib\site-packages\requests\cookies.py", line 334, in __getitem__
    return self._find_no_duplicates(name)
  File "C:\Users\devvr\AppData\Local\Programs\Python\Python38\lib\site-packages\requests\cookies.py", line 413, in _find_no_duplicates
    raise KeyError(f"name={name!r}, domain={domain!r}, path={path!r}")
KeyError: "name='csrftoken', domain=None, path=None"
12680-ERROR-unhandled exception in instance <MyHandler(id=2137121114384, addr='127.0.0.1:51821', user='vrv.lfm@Gmail.com')>
Traceback (most recent call last):
  File "C:\Users\devvr\AppData\Local\Programs\Python\Python38\lib\asyncore.py", line 83, in read
    obj.handle_read_event()
  File "C:\Users\devvr\AppData\Local\Programs\Python\Python38\lib\asyncore.py", line 420, in handle_read_event
    self.handle_read()
  File "C:\Users\devvr\AppData\Local\Programs\Python\Python38\lib\site-packages\pyftpdlib\ioloop.py", line 922, in handle_read
    asynchat.async_chat.handle_read(self)
  File "C:\Users\devvr\AppData\Local\Programs\Python\Python38\lib\asynchat.py", line 171, in handle_read
    self.found_terminator()
  File "C:\Users\devvr\AppData\Local\Programs\Python\Python38\lib\site-packages\pyftpdlib\handlers.py", line 1449, in found_terminator
    self.pre_process_command(line, cmd, arg)
  File "C:\Users\devvr\AppData\Local\Programs\Python\Python38\lib\site-packages\pyftpdlib\handlers.py", line 1498, in pre_process_command
    self.process_command(cmd, arg)
  File "C:\Users\devvr\AppData\Local\Programs\Python\Python38\lib\site-packages\pyftpdlib\handlers.py", line 1577, in process_command
    method(*args, **kwargs)
  File "C:\Users\devvr\AppData\Local\Programs\Python\Python38\lib\site-packages\pyftpdlib\handlers.py", line 2595, in ftp_PASS
    self.authorizer.validate_authentication(self.username, line, self)
  File "a:\code\Current\dj\core\ftp\tempCodeRunnerFile.py", line 134, in validate_authentication
    request = validation_request(username, password)
  File "a:\code\Current\dj\core\ftp\tempCodeRunnerFile.py", line 30, in validation_request
    csrftoken = requests.get(path).cookies['csrftoken']
  File "C:\Users\devvr\AppData\Local\Programs\Python\Python38\lib\site-packages\requests\cookies.py", line 334, in __getitem__
    return self._find_no_duplicates(name)
  File "C:\Users\devvr\AppData\Local\Programs\Python\Python38\lib\site-packages\requests\cookies.py", line 413, in _find_no_duplicates
    raise KeyError(f"name={name!r}, domain={domain!r}, path={path!r}")
KeyError: "name='csrftoken', domain=None, path=None"
12680-ERROR-unhandled exception in instance <MyHandler(id=2137121114384, addr='127.0.0.1:51827', user='vrv.lfm@Gmail.com')>
Traceback (most recent call last):
  File "C:\Users\devvr\AppData\Local\Programs\Python\Python38\lib\asyncore.py", line 83, in read
    obj.handle_read_event()
  File "C:\Users\devvr\AppData\Local\Programs\Python\Python38\lib\asyncore.py", line 420, in handle_read_event
    self.handle_read()
  File "C:\Users\devvr\AppData\Local\Programs\Python\Python38\lib\site-packages\pyftpdlib\ioloop.py", line 922, in handle_read
    asynchat.async_chat.handle_read(self)
  File "C:\Users\devvr\AppData\Local\Programs\Python\Python38\lib\asynchat.py", line 171, in handle_read
    self.found_terminator()
  File "C:\Users\devvr\AppData\Local\Programs\Python\Python38\lib\site-packages\pyftpdlib\handlers.py", line 1449, in found_terminator
    self.pre_process_command(line, cmd, arg)
  File "C:\Users\devvr\AppData\Local\Programs\Python\Python38\lib\site-packages\pyftpdlib\handlers.py", line 1498, in pre_process_command
    self.process_command(cmd, arg)
  File "C:\Users\devvr\AppData\Local\Programs\Python\Python38\lib\site-packages\pyftpdlib\handlers.py", line 1577, in process_command
    method(*args, **kwargs)
  File "C:\Users\devvr\AppData\Local\Programs\Python\Python38\lib\site-packages\pyftpdlib\handlers.py", line 2595, in ftp_PASS
    self.authorizer.validate_authentication(self.username, line, self)
  File "a:\code\Current\dj\core\ftp\tempCodeRunnerFile.py", line 134, in validate_authentication
    request = validation_request(username, password)
  File "a:\code\Current\dj\core\ftp\tempCodeRunnerFile.py", line 30, in validation_request
    csrftoken = requests.get(path).cookies['csrftoken']
  File "C:\Users\devvr\AppData\Local\Programs\Python\Python38\lib\site-packages\requests\cookies.py", line 334, in __getitem__
    return self._find_no_duplicates(name)
  File "C:\Users\devvr\AppData\Local\Programs\Python\Python38\lib\site-packages\requests\cookies.py", line 413, in _find_no_duplicates
    raise KeyError(f"name={name!r}, domain={domain!r}, path={path!r}")
KeyError: "name='csrftoken', domain=None, path=None"
12680-ERROR-unhandled exception in instance <MyHandler(id=2137121114384, addr='127.0.0.1:51829', user='vrv.lfm@Gmail.com')>
Traceback (most recent call last):
  File "C:\Users\devvr\AppData\Local\Programs\Python\Python38\lib\asyncore.py", line 83, in read
    obj.handle_read_event()
  File "C:\Users\devvr\AppData\Local\Programs\Python\Python38\lib\asyncore.py", line 420, in handle_read_event
    self.handle_read()
  File "C:\Users\devvr\AppData\Local\Programs\Python\Python38\lib\site-packages\pyftpdlib\ioloop.py", line 922, in handle_read
    asynchat.async_chat.handle_read(self)
  File "C:\Users\devvr\AppData\Local\Programs\Python\Python38\lib\asynchat.py", line 171, in handle_read
    self.found_terminator()
  File "C:\Users\devvr\AppData\Local\Programs\Python\Python38\lib\site-packages\pyftpdlib\handlers.py", line 1449, in found_terminator
    self.pre_process_command(line, cmd, arg)
  File "C:\Users\devvr\AppData\Local\Programs\Python\Python38\lib\site-packages\pyftpdlib\handlers.py", line 1498, in pre_process_command
    self.process_command(cmd, arg)
  File "C:\Users\devvr\AppData\Local\Programs\Python\Python38\lib\site-packages\pyftpdlib\handlers.py", line 1577, in process_command
    method(*args, **kwargs)
  File "C:\Users\devvr\AppData\Local\Programs\Python\Python38\lib\site-packages\pyftpdlib\handlers.py", line 2595, in ftp_PASS
    self.authorizer.validate_authentication(self.username, line, self)
  File "a:\code\Current\dj\core\ftp\tempCodeRunnerFile.py", line 134, in validate_authentication
    request = validation_request(username, password)
  File "a:\code\Current\dj\core\ftp\tempCodeRunnerFile.py", line 30, in validation_request
    csrftoken = requests.get(path).cookies['csrftoken']
  File "C:\Users\devvr\AppData\Local\Programs\Python\Python38\lib\site-packages\requests\cookies.py", line 334, in __getitem__
    return self._find_no_duplicates(name)
  File "C:\Users\devvr\AppData\Local\Programs\Python\Python38\lib\site-packages\requests\cookies.py", line 413, in _find_no_duplicates
    raise KeyError(f"name={name!r}, domain={domain!r}, path={path!r}")
KeyError: "name='csrftoken', domain=None, path=None"
9876-ERROR-unhandled exception in instance <MyHandler(id=2715197786384, addr='127.0.0.1:51870', user='vrv.lfm@Gmail.com')>
Traceback (most recent call last):
  File "C:\Users\devvr\AppData\Local\Programs\Python\Python38\lib\asyncore.py", line 83, in read
    obj.handle_read_event()
  File "C:\Users\devvr\AppData\Local\Programs\Python\Python38\lib\asyncore.py", line 420, in handle_read_event
    self.handle_read()
  File "C:\Users\devvr\AppData\Local\Programs\Python\Python38\lib\site-packages\pyftpdlib\ioloop.py", line 922, in handle_read
    asynchat.async_chat.handle_read(self)
  File "C:\Users\devvr\AppData\Local\Programs\Python\Python38\lib\asynchat.py", line 171, in handle_read
    self.found_terminator()
  File "C:\Users\devvr\AppData\Local\Programs\Python\Python38\lib\site-packages\pyftpdlib\handlers.py", line 1449, in found_terminator
    self.pre_process_command(line, cmd, arg)
  File "C:\Users\devvr\AppData\Local\Programs\Python\Python38\lib\site-packages\pyftpdlib\handlers.py", line 1498, in pre_process_command
    self.process_command(cmd, arg)
  File "C:\Users\devvr\AppData\Local\Programs\Python\Python38\lib\site-packages\pyftpdlib\handlers.py", line 1577, in process_command
    method(*args, **kwargs)
  File "C:\Users\devvr\AppData\Local\Programs\Python\Python38\lib\site-packages\pyftpdlib\handlers.py", line 2595, in ftp_PASS
    self.authorizer.validate_authentication(self.username, line, self)
  File "a:\code\Current\dj\core\ftp\tempCodeRunnerFile.py", line 134, in validate_authentication
    request = validation_request(username, password)
  File "a:\code\Current\dj\core\ftp\tempCodeRunnerFile.py", line 30, in validation_request
    csrftoken = requests.get(path).cookies['csrftoken']
  File "C:\Users\devvr\AppData\Local\Programs\Python\Python38\lib\site-packages\requests\cookies.py", line 334, in __getitem__
    return self._find_no_duplicates(name)
  File "C:\Users\devvr\AppData\Local\Programs\Python\Python38\lib\site-packages\requests\cookies.py", line 413, in _find_no_duplicates
    raise KeyError(f"name={name!r}, domain={domain!r}, path={path!r}")
KeyError: "name='csrftoken', domain=None, path=None"
9876-ERROR-unhandled exception in instance <MyHandler(id=2715197786384, addr='127.0.0.1:51873', user='vrv.lfm@Gmail.com')>
Traceback (most recent call last):
  File "C:\Users\devvr\AppData\Local\Programs\Python\Python38\lib\asyncore.py", line 83, in read
    obj.handle_read_event()
  File "C:\Users\devvr\AppData\Local\Programs\Python\Python38\lib\asyncore.py", line 420, in handle_read_event
    self.handle_read()
  File "C:\Users\devvr\AppData\Local\Programs\Python\Python38\lib\site-packages\pyftpdlib\ioloop.py", line 922, in handle_read
    asynchat.async_chat.handle_read(self)
  File "C:\Users\devvr\AppData\Local\Programs\Python\Python38\lib\asynchat.py", line 171, in handle_read
    self.found_terminator()
  File "C:\Users\devvr\AppData\Local\Programs\Python\Python38\lib\site-packages\pyftpdlib\handlers.py", line 1449, in found_terminator
    self.pre_process_command(line, cmd, arg)
  File "C:\Users\devvr\AppData\Local\Programs\Python\Python38\lib\site-packages\pyftpdlib\handlers.py", line 1498, in pre_process_command
    self.process_command(cmd, arg)
  File "C:\Users\devvr\AppData\Local\Programs\Python\Python38\lib\site-packages\pyftpdlib\handlers.py", line 1577, in process_command
    method(*args, **kwargs)
  File "C:\Users\devvr\AppData\Local\Programs\Python\Python38\lib\site-packages\pyftpdlib\handlers.py", line 2595, in ftp_PASS
    self.authorizer.validate_authentication(self.username, line, self)
  File "a:\code\Current\dj\core\ftp\tempCodeRunnerFile.py", line 134, in validate_authentication
    request = validation_request(username, password)
  File "a:\code\Current\dj\core\ftp\tempCodeRunnerFile.py", line 30, in validation_request
    csrftoken = requests.get(path).cookies['csrftoken']
  File "C:\Users\devvr\AppData\Local\Programs\Python\Python38\lib\site-packages\requests\cookies.py", line 334, in __getitem__
    return self._find_no_duplicates(name)
  File "C:\Users\devvr\AppData\Local\Programs\Python\Python38\lib\site-packages\requests\cookies.py", line 413, in _find_no_duplicates
    raise KeyError(f"name={name!r}, domain={domain!r}, path={path!r}")
KeyError: "name='csrftoken', domain=None, path=None"
9876-ERROR-unhandled exception in instance <MyHandler(id=2715197786384, addr='127.0.0.1:51886', user='vrv.lfm@Gmail.com')>
Traceback (most recent call last):
  File "C:\Users\devvr\AppData\Local\Programs\Python\Python38\lib\asyncore.py", line 83, in read
    obj.handle_read_event()
  File "C:\Users\devvr\AppData\Local\Programs\Python\Python38\lib\asyncore.py", line 420, in handle_read_event
    self.handle_read()
  File "C:\Users\devvr\AppData\Local\Programs\Python\Python38\lib\site-packages\pyftpdlib\ioloop.py", line 922, in handle_read
    asynchat.async_chat.handle_read(self)
  File "C:\Users\devvr\AppData\Local\Programs\Python\Python38\lib\asynchat.py", line 171, in handle_read
    self.found_terminator()
  File "C:\Users\devvr\AppData\Local\Programs\Python\Python38\lib\site-packages\pyftpdlib\handlers.py", line 1449, in found_terminator
    self.pre_process_command(line, cmd, arg)
  File "C:\Users\devvr\AppData\Local\Programs\Python\Python38\lib\site-packages\pyftpdlib\handlers.py", line 1498, in pre_process_command
    self.process_command(cmd, arg)
  File "C:\Users\devvr\AppData\Local\Programs\Python\Python38\lib\site-packages\pyftpdlib\handlers.py", line 1577, in process_command
    method(*args, **kwargs)
  File "C:\Users\devvr\AppData\Local\Programs\Python\Python38\lib\site-packages\pyftpdlib\handlers.py", line 2595, in ftp_PASS
    self.authorizer.validate_authentication(self.username, line, self)
  File "a:\code\Current\dj\core\ftp\tempCodeRunnerFile.py", line 134, in validate_authentication
    request = validation_request(username, password)
  File "a:\code\Current\dj\core\ftp\tempCodeRunnerFile.py", line 30, in validation_request
    csrftoken = requests.get(path).cookies['csrftoken']
  File "C:\Users\devvr\AppData\Local\Programs\Python\Python38\lib\site-packages\requests\cookies.py", line 334, in __getitem__
    return self._find_no_duplicates(name)
  File "C:\Users\devvr\AppData\Local\Programs\Python\Python38\lib\site-packages\requests\cookies.py", line 413, in _find_no_duplicates
    raise KeyError(f"name={name!r}, domain={domain!r}, path={path!r}")
KeyError: "name='csrftoken', domain=None, path=None"
9876-ERROR-unhandled exception in instance <MyHandler(id=2715197786384, addr='127.0.0.1:51888', user='vrv.lfm@Gmail.com')>
Traceback (most recent call last):
  File "C:\Users\devvr\AppData\Local\Programs\Python\Python38\lib\asyncore.py", line 83, in read
    obj.handle_read_event()
  File "C:\Users\devvr\AppData\Local\Programs\Python\Python38\lib\asyncore.py", line 420, in handle_read_event
    self.handle_read()
  File "C:\Users\devvr\AppData\Local\Programs\Python\Python38\lib\site-packages\pyftpdlib\ioloop.py", line 922, in handle_read
    asynchat.async_chat.handle_read(self)
  File "C:\Users\devvr\AppData\Local\Programs\Python\Python38\lib\asynchat.py", line 171, in handle_read
    self.found_terminator()
  File "C:\Users\devvr\AppData\Local\Programs\Python\Python38\lib\site-packages\pyftpdlib\handlers.py", line 1449, in found_terminator
    self.pre_process_command(line, cmd, arg)
  File "C:\Users\devvr\AppData\Local\Programs\Python\Python38\lib\site-packages\pyftpdlib\handlers.py", line 1498, in pre_process_command
    self.process_command(cmd, arg)
  File "C:\Users\devvr\AppData\Local\Programs\Python\Python38\lib\site-packages\pyftpdlib\handlers.py", line 1577, in process_command
    method(*args, **kwargs)
  File "C:\Users\devvr\AppData\Local\Programs\Python\Python38\lib\site-packages\pyftpdlib\handlers.py", line 2595, in ftp_PASS
    self.authorizer.validate_authentication(self.username, line, self)
  File "a:\code\Current\dj\core\ftp\tempCodeRunnerFile.py", line 134, in validate_authentication
    request = validation_request(username, password)
  File "a:\code\Current\dj\core\ftp\tempCodeRunnerFile.py", line 30, in validation_request
    csrftoken = requests.get(path).cookies['csrftoken']
  File "C:\Users\devvr\AppData\Local\Programs\Python\Python38\lib\site-packages\requests\cookies.py", line 334, in __getitem__
    return self._find_no_duplicates(name)
  File "C:\Users\devvr\AppData\Local\Programs\Python\Python38\lib\site-packages\requests\cookies.py", line 413, in _find_no_duplicates
    raise KeyError(f"name={name!r}, domain={domain!r}, path={path!r}")
KeyError: "name='csrftoken', domain=None, path=None"
9876-ERROR-unhandled exception in instance <MyHandler(id=2715197786384, addr='127.0.0.1:51895', user='vrv.lfm@Gmail.com')>
Traceback (most recent call last):
  File "C:\Users\devvr\AppData\Local\Programs\Python\Python38\lib\asyncore.py", line 83, in read
    obj.handle_read_event()
  File "C:\Users\devvr\AppData\Local\Programs\Python\Python38\lib\asyncore.py", line 420, in handle_read_event
    self.handle_read()
  File "C:\Users\devvr\AppData\Local\Programs\Python\Python38\lib\site-packages\pyftpdlib\ioloop.py", line 922, in handle_read
    asynchat.async_chat.handle_read(self)
  File "C:\Users\devvr\AppData\Local\Programs\Python\Python38\lib\asynchat.py", line 171, in handle_read
    self.found_terminator()
  File "C:\Users\devvr\AppData\Local\Programs\Python\Python38\lib\site-packages\pyftpdlib\handlers.py", line 1449, in found_terminator
    self.pre_process_command(line, cmd, arg)
  File "C:\Users\devvr\AppData\Local\Programs\Python\Python38\lib\site-packages\pyftpdlib\handlers.py", line 1498, in pre_process_command
    self.process_command(cmd, arg)
  File "C:\Users\devvr\AppData\Local\Programs\Python\Python38\lib\site-packages\pyftpdlib\handlers.py", line 1577, in process_command
    method(*args, **kwargs)
  File "C:\Users\devvr\AppData\Local\Programs\Python\Python38\lib\site-packages\pyftpdlib\handlers.py", line 2595, in ftp_PASS
    self.authorizer.validate_authentication(self.username, line, self)
  File "a:\code\Current\dj\core\ftp\tempCodeRunnerFile.py", line 134, in validate_authentication
    request = validation_request(username, password)
  File "a:\code\Current\dj\core\ftp\tempCodeRunnerFile.py", line 30, in validation_request
    csrftoken = requests.get(path).cookies['csrftoken']
  File "C:\Users\devvr\AppData\Local\Programs\Python\Python38\lib\site-packages\requests\cookies.py", line 334, in __getitem__
    return self._find_no_duplicates(name)
  File "C:\Users\devvr\AppData\Local\Programs\Python\Python38\lib\site-packages\requests\cookies.py", line 413, in _find_no_duplicates
    raise KeyError(f"name={name!r}, domain={domain!r}, path={path!r}")
KeyError: "name='csrftoken', domain=None, path=None"
9876-ERROR-unhandled exception in instance <MyHandler(id=2715197786384, addr='127.0.0.1:51899', user='vrv.lfm@Gmail.com')>
Traceback (most recent call last):
  File "C:\Users\devvr\AppData\Local\Programs\Python\Python38\lib\asyncore.py", line 83, in read
    obj.handle_read_event()
  File "C:\Users\devvr\AppData\Local\Programs\Python\Python38\lib\asyncore.py", line 420, in handle_read_event
    self.handle_read()
  File "C:\Users\devvr\AppData\Local\Programs\Python\Python38\lib\site-packages\pyftpdlib\ioloop.py", line 922, in handle_read
    asynchat.async_chat.handle_read(self)
  File "C:\Users\devvr\AppData\Local\Programs\Python\Python38\lib\asynchat.py", line 171, in handle_read
    self.found_terminator()
  File "C:\Users\devvr\AppData\Local\Programs\Python\Python38\lib\site-packages\pyftpdlib\handlers.py", line 1449, in found_terminator
    self.pre_process_command(line, cmd, arg)
  File "C:\Users\devvr\AppData\Local\Programs\Python\Python38\lib\site-packages\pyftpdlib\handlers.py", line 1498, in pre_process_command
    self.process_command(cmd, arg)
  File "C:\Users\devvr\AppData\Local\Programs\Python\Python38\lib\site-packages\pyftpdlib\handlers.py", line 1577, in process_command
    method(*args, **kwargs)
  File "C:\Users\devvr\AppData\Local\Programs\Python\Python38\lib\site-packages\pyftpdlib\handlers.py", line 2595, in ftp_PASS
    self.authorizer.validate_authentication(self.username, line, self)
  File "a:\code\Current\dj\core\ftp\tempCodeRunnerFile.py", line 134, in validate_authentication
    request = validation_request(username, password)
  File "a:\code\Current\dj\core\ftp\tempCodeRunnerFile.py", line 30, in validation_request
    csrftoken = requests.get(path).cookies['csrftoken']
  File "C:\Users\devvr\AppData\Local\Programs\Python\Python38\lib\site-packages\requests\cookies.py", line 334, in __getitem__
    return self._find_no_duplicates(name)
  File "C:\Users\devvr\AppData\Local\Programs\Python\Python38\lib\site-packages\requests\cookies.py", line 413, in _find_no_duplicates
    raise KeyError(f"name={name!r}, domain={domain!r}, path={path!r}")
KeyError: "name='csrftoken', domain=None, path=None"
12440-ERROR-unhandled exception in instance <MyHandler(id=1982223370512, addr='127.0.0.1:51906', user='vrv.lfm@Gmail.com')>
Traceback (most recent call last):
  File "C:\Users\devvr\AppData\Local\Programs\Python\Python38\lib\asyncore.py", line 83, in read
    obj.handle_read_event()
  File "C:\Users\devvr\AppData\Local\Programs\Python\Python38\lib\asyncore.py", line 420, in handle_read_event
    self.handle_read()
  File "C:\Users\devvr\AppData\Local\Programs\Python\Python38\lib\site-packages\pyftpdlib\ioloop.py", line 922, in handle_read
    asynchat.async_chat.handle_read(self)
  File "C:\Users\devvr\AppData\Local\Programs\Python\Python38\lib\asynchat.py", line 171, in handle_read
    self.found_terminator()
  File "C:\Users\devvr\AppData\Local\Programs\Python\Python38\lib\site-packages\pyftpdlib\handlers.py", line 1449, in found_terminator
    self.pre_process_command(line, cmd, arg)
  File "C:\Users\devvr\AppData\Local\Programs\Python\Python38\lib\site-packages\pyftpdlib\handlers.py", line 1498, in pre_process_command
    self.process_command(cmd, arg)
  File "C:\Users\devvr\AppData\Local\Programs\Python\Python38\lib\site-packages\pyftpdlib\handlers.py", line 1577, in process_command
    method(*args, **kwargs)
  File "C:\Users\devvr\AppData\Local\Programs\Python\Python38\lib\site-packages\pyftpdlib\handlers.py", line 2595, in ftp_PASS
    self.authorizer.validate_authentication(self.username, line, self)
  File "a:\code\Current\dj\core\ftp\tempCodeRunnerFile.py", line 134, in validate_authentication
    request = validation_request(username, password)
  File "a:\code\Current\dj\core\ftp\tempCodeRunnerFile.py", line 30, in validation_request
    csrftoken = requests.get(path).cookies['csrftoken']
  File "C:\Users\devvr\AppData\Local\Programs\Python\Python38\lib\site-packages\requests\cookies.py", line 334, in __getitem__
    return self._find_no_duplicates(name)
  File "C:\Users\devvr\AppData\Local\Programs\Python\Python38\lib\site-packages\requests\cookies.py", line 413, in _find_no_duplicates
    raise KeyError(f"name={name!r}, domain={domain!r}, path={path!r}")
KeyError: "name='csrftoken', domain=None, path=None"
12440-ERROR-unhandled exception in instance <MyHandler(id=1982223370512, addr='127.0.0.1:51908', user='vrv.lfm@Gmail.com')>
Traceback (most recent call last):
  File "C:\Users\devvr\AppData\Local\Programs\Python\Python38\lib\asyncore.py", line 83, in read
    obj.handle_read_event()
  File "C:\Users\devvr\AppData\Local\Programs\Python\Python38\lib\asyncore.py", line 420, in handle_read_event
    self.handle_read()
  File "C:\Users\devvr\AppData\Local\Programs\Python\Python38\lib\site-packages\pyftpdlib\ioloop.py", line 922, in handle_read
    asynchat.async_chat.handle_read(self)
  File "C:\Users\devvr\AppData\Local\Programs\Python\Python38\lib\asynchat.py", line 171, in handle_read
    self.found_terminator()
  File "C:\Users\devvr\AppData\Local\Programs\Python\Python38\lib\site-packages\pyftpdlib\handlers.py", line 1449, in found_terminator
    self.pre_process_command(line, cmd, arg)
  File "C:\Users\devvr\AppData\Local\Programs\Python\Python38\lib\site-packages\pyftpdlib\handlers.py", line 1498, in pre_process_command
    self.process_command(cmd, arg)
  File "C:\Users\devvr\AppData\Local\Programs\Python\Python38\lib\site-packages\pyftpdlib\handlers.py", line 1577, in process_command
    method(*args, **kwargs)
  File "C:\Users\devvr\AppData\Local\Programs\Python\Python38\lib\site-packages\pyftpdlib\handlers.py", line 2595, in ftp_PASS
    self.authorizer.validate_authentication(self.username, line, self)
  File "a:\code\Current\dj\core\ftp\tempCodeRunnerFile.py", line 134, in validate_authentication
    request = validation_request(username, password)
  File "a:\code\Current\dj\core\ftp\tempCodeRunnerFile.py", line 30, in validation_request
    csrftoken = requests.get(path).cookies['csrftoken']
  File "C:\Users\devvr\AppData\Local\Programs\Python\Python38\lib\site-packages\requests\cookies.py", line 334, in __getitem__
    return self._find_no_duplicates(name)
  File "C:\Users\devvr\AppData\Local\Programs\Python\Python38\lib\site-packages\requests\cookies.py", line 413, in _find_no_duplicates
    raise KeyError(f"name={name!r}, domain={domain!r}, path={path!r}")
KeyError: "name='csrftoken', domain=None, path=None"
2748-ERROR-unhandled exception in instance <MyHandler(id=2153323841760, addr='127.0.0.1:51922', user='vrv.lfm@Gmail.com')>
Traceback (most recent call last):
  File "C:\Users\devvr\AppData\Local\Programs\Python\Python38\lib\asyncore.py", line 83, in read
    obj.handle_read_event()
  File "C:\Users\devvr\AppData\Local\Programs\Python\Python38\lib\asyncore.py", line 420, in handle_read_event
    self.handle_read()
  File "C:\Users\devvr\AppData\Local\Programs\Python\Python38\lib\site-packages\pyftpdlib\ioloop.py", line 922, in handle_read
    asynchat.async_chat.handle_read(self)
  File "C:\Users\devvr\AppData\Local\Programs\Python\Python38\lib\asynchat.py", line 171, in handle_read
    self.found_terminator()
  File "C:\Users\devvr\AppData\Local\Programs\Python\Python38\lib\site-packages\pyftpdlib\handlers.py", line 1449, in found_terminator
    self.pre_process_command(line, cmd, arg)
  File "C:\Users\devvr\AppData\Local\Programs\Python\Python38\lib\site-packages\pyftpdlib\handlers.py", line 1498, in pre_process_command
    self.process_command(cmd, arg)
  File "C:\Users\devvr\AppData\Local\Programs\Python\Python38\lib\site-packages\pyftpdlib\handlers.py", line 1577, in process_command
    method(*args, **kwargs)
  File "C:\Users\devvr\AppData\Local\Programs\Python\Python38\lib\site-packages\pyftpdlib\handlers.py", line 2595, in ftp_PASS
    self.authorizer.validate_authentication(self.username, line, self)
  File "a:\code\Current\dj\core\ftp\tempCodeRunnerFile.py", line 136, in validate_authentication
    request = validation_request(username, password)
  File "a:\code\Current\dj\core\ftp\tempCodeRunnerFile.py", line 30, in validation_request
    csrftoken = requests.get(path).cookies['csrftoken']
  File "C:\Users\devvr\AppData\Local\Programs\Python\Python38\lib\site-packages\requests\cookies.py", line 334, in __getitem__
    return self._find_no_duplicates(name)
  File "C:\Users\devvr\AppData\Local\Programs\Python\Python38\lib\site-packages\requests\cookies.py", line 413, in _find_no_duplicates
    raise KeyError(f"name={name!r}, domain={domain!r}, path={path!r}")
KeyError: "name='csrftoken', domain=None, path=None"
2748-ERROR-unhandled exception in instance <MyHandler(id=2153323841760, addr='127.0.0.1:51925', user='vrv.lfm@Gmail.com')>
Traceback (most recent call last):
  File "C:\Users\devvr\AppData\Local\Programs\Python\Python38\lib\asyncore.py", line 83, in read
    obj.handle_read_event()
  File "C:\Users\devvr\AppData\Local\Programs\Python\Python38\lib\asyncore.py", line 420, in handle_read_event
    self.handle_read()
  File "C:\Users\devvr\AppData\Local\Programs\Python\Python38\lib\site-packages\pyftpdlib\ioloop.py", line 922, in handle_read
    asynchat.async_chat.handle_read(self)
  File "C:\Users\devvr\AppData\Local\Programs\Python\Python38\lib\asynchat.py", line 171, in handle_read
    self.found_terminator()
  File "C:\Users\devvr\AppData\Local\Programs\Python\Python38\lib\site-packages\pyftpdlib\handlers.py", line 1449, in found_terminator
    self.pre_process_command(line, cmd, arg)
  File "C:\Users\devvr\AppData\Local\Programs\Python\Python38\lib\site-packages\pyftpdlib\handlers.py", line 1498, in pre_process_command
    self.process_command(cmd, arg)
  File "C:\Users\devvr\AppData\Local\Programs\Python\Python38\lib\site-packages\pyftpdlib\handlers.py", line 1577, in process_command
    method(*args, **kwargs)
  File "C:\Users\devvr\AppData\Local\Programs\Python\Python38\lib\site-packages\pyftpdlib\handlers.py", line 2595, in ftp_PASS
    self.authorizer.validate_authentication(self.username, line, self)
  File "a:\code\Current\dj\core\ftp\tempCodeRunnerFile.py", line 136, in validate_authentication
    request = validation_request(username, password)
  File "a:\code\Current\dj\core\ftp\tempCodeRunnerFile.py", line 30, in validation_request
    csrftoken = requests.get(path).cookies['csrftoken']
  File "C:\Users\devvr\AppData\Local\Programs\Python\Python38\lib\site-packages\requests\cookies.py", line 334, in __getitem__
    return self._find_no_duplicates(name)
  File "C:\Users\devvr\AppData\Local\Programs\Python\Python38\lib\site-packages\requests\cookies.py", line 413, in _find_no_duplicates
    raise KeyError(f"name={name!r}, domain={domain!r}, path={path!r}")
KeyError: "name='csrftoken', domain=None, path=None"
